WARNING 2025-02-15 12:41:18,807 signals Permissões do usuário marcelowkr foram alteradas.
ERROR 2025-02-15 21:32:30,353 log Internal Server Error: /control-assessments/
Traceback (most recent call last):
  File "C:\Users\ResTIC16\Documents\cybersec-project\venv\Lib\site-packages\django\core\handlers\exception.py", line 55, in inner
    response = get_response(request)
  File "C:\Users\ResTIC16\Documents\cybersec-project\venv\Lib\site-packages\django\core\handlers\base.py", line 197, in _get_response
    response = wrapped_callback(request, *callback_args, **callback_kwargs)
  File "C:\Users\ResTIC16\Documents\cybersec-project\venv\Lib\site-packages\django\views\decorators\csrf.py", line 65, in _view_wrapper
    return view_func(request, *args, **kwargs)
  File "C:\Users\ResTIC16\Documents\cybersec-project\venv\Lib\site-packages\rest_framework\viewsets.py", line 124, in view
    return self.dispatch(request, *args, **kwargs)
           ~~~~~~~~~~~~~^^^^^^^^^^^^^^^^^^^^^^^^^^
  File "C:\Users\ResTIC16\Documents\cybersec-project\venv\Lib\site-packages\rest_framework\views.py", line 509, in dispatch
    response = self.handle_exception(exc)
  File "C:\Users\ResTIC16\Documents\cybersec-project\venv\Lib\site-packages\rest_framework\views.py", line 469, in handle_exception
    self.raise_uncaught_exception(exc)
    ~~~~~~~~~~~~~~~~~~~~~~~~~~~~~^^^^^
  File "C:\Users\ResTIC16\Documents\cybersec-project\venv\Lib\site-packages\rest_framework\views.py", line 480, in raise_uncaught_exception
    raise exc
  File "C:\Users\ResTIC16\Documents\cybersec-project\venv\Lib\site-packages\rest_framework\views.py", line 506, in dispatch
    response = handler(request, *args, **kwargs)
  File "C:\Users\ResTIC16\Documents\cybersec-project\venv\Lib\site-packages\rest_framework\mixins.py", line 45, in list
    serializer = self.get_serializer(queryset, many=True)
  File "C:\Users\ResTIC16\Documents\cybersec-project\venv\Lib\site-packages\rest_framework\generics.py", line 112, in get_serializer
    serializer_class = self.get_serializer_class()
  File "C:\Users\ResTIC16\Documents\cybersec-project\venv\Lib\site-packages\rest_framework\generics.py", line 126, in get_serializer_class
    assert self.serializer_class is not None, (
           ^^^^^^^^^^^^^^^^^^^^^^^^^^^^^^^^^
AssertionError: 'ControlAssessmentViewSet' should either include a `serializer_class` attribute, or override the `get_serializer_class()` method.
ERROR 2025-02-15 21:32:36,184 log Internal Server Error: /control-assessments/
Traceback (most recent call last):
  File "C:\Users\ResTIC16\Documents\cybersec-project\venv\Lib\site-packages\django\core\handlers\exception.py", line 55, in inner
    response = get_response(request)
  File "C:\Users\ResTIC16\Documents\cybersec-project\venv\Lib\site-packages\django\core\handlers\base.py", line 197, in _get_response
    response = wrapped_callback(request, *callback_args, **callback_kwargs)
  File "C:\Users\ResTIC16\Documents\cybersec-project\venv\Lib\site-packages\django\views\decorators\csrf.py", line 65, in _view_wrapper
    return view_func(request, *args, **kwargs)
  File "C:\Users\ResTIC16\Documents\cybersec-project\venv\Lib\site-packages\rest_framework\viewsets.py", line 124, in view
    return self.dispatch(request, *args, **kwargs)
           ~~~~~~~~~~~~~^^^^^^^^^^^^^^^^^^^^^^^^^^
  File "C:\Users\ResTIC16\Documents\cybersec-project\venv\Lib\site-packages\rest_framework\views.py", line 509, in dispatch
    response = self.handle_exception(exc)
  File "C:\Users\ResTIC16\Documents\cybersec-project\venv\Lib\site-packages\rest_framework\views.py", line 469, in handle_exception
    self.raise_uncaught_exception(exc)
    ~~~~~~~~~~~~~~~~~~~~~~~~~~~~~^^^^^
  File "C:\Users\ResTIC16\Documents\cybersec-project\venv\Lib\site-packages\rest_framework\views.py", line 480, in raise_uncaught_exception
    raise exc
  File "C:\Users\ResTIC16\Documents\cybersec-project\venv\Lib\site-packages\rest_framework\views.py", line 506, in dispatch
    response = handler(request, *args, **kwargs)
  File "C:\Users\ResTIC16\Documents\cybersec-project\venv\Lib\site-packages\rest_framework\mixins.py", line 45, in list
    serializer = self.get_serializer(queryset, many=True)
  File "C:\Users\ResTIC16\Documents\cybersec-project\venv\Lib\site-packages\rest_framework\generics.py", line 112, in get_serializer
    serializer_class = self.get_serializer_class()
  File "C:\Users\ResTIC16\Documents\cybersec-project\venv\Lib\site-packages\rest_framework\generics.py", line 126, in get_serializer_class
    assert self.serializer_class is not None, (
           ^^^^^^^^^^^^^^^^^^^^^^^^^^^^^^^^^
AssertionError: 'ControlAssessmentViewSet' should either include a `serializer_class` attribute, or override the `get_serializer_class()` method.
ERROR 2025-02-15 21:32:38,683 log Internal Server Error: /control-assessments/
Traceback (most recent call last):
  File "C:\Users\ResTIC16\Documents\cybersec-project\venv\Lib\site-packages\django\core\handlers\exception.py", line 55, in inner
    response = get_response(request)
  File "C:\Users\ResTIC16\Documents\cybersec-project\venv\Lib\site-packages\django\core\handlers\base.py", line 197, in _get_response
    response = wrapped_callback(request, *callback_args, **callback_kwargs)
  File "C:\Users\ResTIC16\Documents\cybersec-project\venv\Lib\site-packages\django\views\decorators\csrf.py", line 65, in _view_wrapper
    return view_func(request, *args, **kwargs)
  File "C:\Users\ResTIC16\Documents\cybersec-project\venv\Lib\site-packages\rest_framework\viewsets.py", line 124, in view
    return self.dispatch(request, *args, **kwargs)
           ~~~~~~~~~~~~~^^^^^^^^^^^^^^^^^^^^^^^^^^
  File "C:\Users\ResTIC16\Documents\cybersec-project\venv\Lib\site-packages\rest_framework\views.py", line 509, in dispatch
    response = self.handle_exception(exc)
  File "C:\Users\ResTIC16\Documents\cybersec-project\venv\Lib\site-packages\rest_framework\views.py", line 469, in handle_exception
    self.raise_uncaught_exception(exc)
    ~~~~~~~~~~~~~~~~~~~~~~~~~~~~~^^^^^
  File "C:\Users\ResTIC16\Documents\cybersec-project\venv\Lib\site-packages\rest_framework\views.py", line 480, in raise_uncaught_exception
    raise exc
  File "C:\Users\ResTIC16\Documents\cybersec-project\venv\Lib\site-packages\rest_framework\views.py", line 506, in dispatch
    response = handler(request, *args, **kwargs)
  File "C:\Users\ResTIC16\Documents\cybersec-project\venv\Lib\site-packages\rest_framework\mixins.py", line 45, in list
    serializer = self.get_serializer(queryset, many=True)
  File "C:\Users\ResTIC16\Documents\cybersec-project\venv\Lib\site-packages\rest_framework\generics.py", line 112, in get_serializer
    serializer_class = self.get_serializer_class()
  File "C:\Users\ResTIC16\Documents\cybersec-project\venv\Lib\site-packages\rest_framework\generics.py", line 126, in get_serializer_class
    assert self.serializer_class is not None, (
           ^^^^^^^^^^^^^^^^^^^^^^^^^^^^^^^^^
AssertionError: 'ControlAssessmentViewSet' should either include a `serializer_class` attribute, or override the `get_serializer_class()` method.
ERROR 2025-02-15 21:42:42,777 log Internal Server Error: /control-assessments/
Traceback (most recent call last):
  File "C:\Users\ResTIC16\Documents\cybersec-project\venv\Lib\site-packages\django\db\backends\utils.py", line 105, in _execute
    return self.cursor.execute(sql, params)
           ~~~~~~~~~~~~~~~~~~~^^^^^^^^^^^^^
  File "C:\Users\ResTIC16\Documents\cybersec-project\venv\Lib\site-packages\django\db\backends\sqlite3\base.py", line 354, in execute
    return super().execute(query, params)
           ~~~~~~~~~~~~~~~^^^^^^^^^^^^^^^
sqlite3.OperationalError: no such table: core_controlassessment

The above exception was the direct cause of the following exception:

Traceback (most recent call last):
  File "C:\Users\ResTIC16\Documents\cybersec-project\venv\Lib\site-packages\django\core\handlers\exception.py", line 55, in inner
    response = get_response(request)
  File "C:\Users\ResTIC16\Documents\cybersec-project\venv\Lib\site-packages\django\core\handlers\base.py", line 197, in _get_response
    response = wrapped_callback(request, *callback_args, **callback_kwargs)
  File "C:\Users\ResTIC16\Documents\cybersec-project\venv\Lib\site-packages\django\views\decorators\csrf.py", line 65, in _view_wrapper
    return view_func(request, *args, **kwargs)
  File "C:\Users\ResTIC16\Documents\cybersec-project\venv\Lib\site-packages\rest_framework\viewsets.py", line 124, in view
    return self.dispatch(request, *args, **kwargs)
           ~~~~~~~~~~~~~^^^^^^^^^^^^^^^^^^^^^^^^^^
  File "C:\Users\ResTIC16\Documents\cybersec-project\venv\Lib\site-packages\rest_framework\views.py", line 509, in dispatch
    response = self.handle_exception(exc)
  File "C:\Users\ResTIC16\Documents\cybersec-project\venv\Lib\site-packages\rest_framework\views.py", line 469, in handle_exception
    self.raise_uncaught_exception(exc)
    ~~~~~~~~~~~~~~~~~~~~~~~~~~~~~^^^^^
  File "C:\Users\ResTIC16\Documents\cybersec-project\venv\Lib\site-packages\rest_framework\views.py", line 480, in raise_uncaught_exception
    raise exc
  File "C:\Users\ResTIC16\Documents\cybersec-project\venv\Lib\site-packages\rest_framework\views.py", line 506, in dispatch
    response = handler(request, *args, **kwargs)
  File "C:\Users\ResTIC16\Documents\cybersec-project\venv\Lib\site-packages\rest_framework\mixins.py", line 46, in list
    return Response(serializer.data)
                    ^^^^^^^^^^^^^^^
  File "C:\Users\ResTIC16\Documents\cybersec-project\venv\Lib\site-packages\rest_framework\serializers.py", line 795, in data
    ret = super().data
          ^^^^^^^^^^^^
  File "C:\Users\ResTIC16\Documents\cybersec-project\venv\Lib\site-packages\rest_framework\serializers.py", line 249, in data
    self._data = self.to_representation(self.instance)
                 ~~~~~~~~~~~~~~~~~~~~~~^^^^^^^^^^^^^^^
  File "C:\Users\ResTIC16\Documents\cybersec-project\venv\Lib\site-packages\rest_framework\serializers.py", line 714, in to_representation
    self.child.to_representation(item) for item in iterable
                                                   ^^^^^^^^
  File "C:\Users\ResTIC16\Documents\cybersec-project\venv\Lib\site-packages\django\db\models\query.py", line 400, in __iter__
    self._fetch_all()
    ~~~~~~~~~~~~~~~^^
  File "C:\Users\ResTIC16\Documents\cybersec-project\venv\Lib\site-packages\django\db\models\query.py", line 1928, in _fetch_all
    self._result_cache = list(self._iterable_class(self))
                         ~~~~^^^^^^^^^^^^^^^^^^^^^^^^^^^^
  File "C:\Users\ResTIC16\Documents\cybersec-project\venv\Lib\site-packages\django\db\models\query.py", line 91, in __iter__
    results = compiler.execute_sql(
        chunked_fetch=self.chunked_fetch, chunk_size=self.chunk_size
    )
  File "C:\Users\ResTIC16\Documents\cybersec-project\venv\Lib\site-packages\django\db\models\sql\compiler.py", line 1574, in execute_sql
    cursor.execute(sql, params)
    ~~~~~~~~~~~~~~^^^^^^^^^^^^^
  File "C:\Users\ResTIC16\Documents\cybersec-project\venv\Lib\site-packages\django\db\backends\utils.py", line 122, in execute
    return super().execute(sql, params)
           ~~~~~~~~~~~~~~~^^^^^^^^^^^^^
  File "C:\Users\ResTIC16\Documents\cybersec-project\venv\Lib\site-packages\django\db\backends\utils.py", line 79, in execute
    return self._execute_with_wrappers(
           ~~~~~~~~~~~~~~~~~~~~~~~~~~~^
        sql, params, many=False, executor=self._execute
        ^^^^^^^^^^^^^^^^^^^^^^^^^^^^^^^^^^^^^^^^^^^^^^^
    )
    ^
  File "C:\Users\ResTIC16\Documents\cybersec-project\venv\Lib\site-packages\django\db\backends\utils.py", line 92, in _execute_with_wrappers
    return executor(sql, params, many, context)
  File "C:\Users\ResTIC16\Documents\cybersec-project\venv\Lib\site-packages\django\db\backends\utils.py", line 100, in _execute
    with self.db.wrap_database_errors:
         ^^^^^^^^^^^^^^^^^^^^^^^^^^^^
  File "C:\Users\ResTIC16\Documents\cybersec-project\venv\Lib\site-packages\django\db\utils.py", line 91, in __exit__
    raise dj_exc_value.with_traceback(traceback) from exc_value
  File "C:\Users\ResTIC16\Documents\cybersec-project\venv\Lib\site-packages\django\db\backends\utils.py", line 105, in _execute
    return self.cursor.execute(sql, params)
           ~~~~~~~~~~~~~~~~~~~^^^^^^^^^^^^^
  File "C:\Users\ResTIC16\Documents\cybersec-project\venv\Lib\site-packages\django\db\backends\sqlite3\base.py", line 354, in execute
    return super().execute(query, params)
           ~~~~~~~~~~~~~~~^^^^^^^^^^^^^^^
django.db.utils.OperationalError: no such table: core_controlassessment
ERROR 2025-02-15 22:49:41,346 log Internal Server Error: /api/token
Traceback (most recent call last):
  File "C:\Users\ResTIC16\Documents\cybersec-project\venv\Lib\site-packages\django\core\handlers\exception.py", line 55, in inner
    response = get_response(request)
  File "C:\Users\ResTIC16\Documents\cybersec-project\venv\Lib\site-packages\django\utils\deprecation.py", line 131, in __call__
    response = self.process_response(request, response)
  File "C:\Users\ResTIC16\Documents\cybersec-project\venv\Lib\site-packages\django\middleware\common.py", line 108, in process_response
    return self.response_redirect_class(self.get_full_path_with_slash(request))
                                        ~~~~~~~~~~~~~~~~~~~~~~~~~~~~~^^^^^^^^^
  File "C:\Users\ResTIC16\Documents\cybersec-project\venv\Lib\site-packages\django\middleware\common.py", line 87, in get_full_path_with_slash
    raise RuntimeError(
    ...<9 lines>...
    )
RuntimeError: You called this URL via POST, but the URL doesn't end in a slash and you have APPEND_SLASH set. Django can't redirect to the slash URL while maintaining POST data. Change your form to point to localhost:8000/api/token/ (note the trailing slash), or set APPEND_SLASH=False in your Django settings.
ERROR 2025-02-16 21:45:53,278 log Internal Server Error: /compliance/
Traceback (most recent call last):
  File "C:\Users\ResTIC16\Documents\cybersec-project\venv\Lib\site-packages\django\db\backends\utils.py", line 105, in _execute
    return self.cursor.execute(sql, params)
           ~~~~~~~~~~~~~~~~~~~^^^^^^^^^^^^^
  File "C:\Users\ResTIC16\Documents\cybersec-project\venv\Lib\site-packages\django\db\backends\sqlite3\base.py", line 354, in execute
    return super().execute(query, params)
           ~~~~~~~~~~~~~~~^^^^^^^^^^^^^^^
sqlite3.OperationalError: no such table: core_standard

The above exception was the direct cause of the following exception:

Traceback (most recent call last):
  File "C:\Users\ResTIC16\Documents\cybersec-project\venv\Lib\site-packages\django\core\handlers\exception.py", line 55, in inner
    response = get_response(request)
  File "C:\Users\ResTIC16\Documents\cybersec-project\venv\Lib\site-packages\django\core\handlers\base.py", line 197, in _get_response
    response = wrapped_callback(request, *callback_args, **callback_kwargs)
  File "C:\Users\ResTIC16\Documents\cybersec-project\venv\Lib\site-packages\django\views\decorators\csrf.py", line 65, in _view_wrapper
    return view_func(request, *args, **kwargs)
  File "C:\Users\ResTIC16\Documents\cybersec-project\venv\Lib\site-packages\django\views\generic\base.py", line 104, in view
    return self.dispatch(request, *args, **kwargs)
           ~~~~~~~~~~~~~^^^^^^^^^^^^^^^^^^^^^^^^^^
  File "C:\Users\ResTIC16\Documents\cybersec-project\venv\Lib\site-packages\rest_framework\views.py", line 509, in dispatch
    response = self.handle_exception(exc)
  File "C:\Users\ResTIC16\Documents\cybersec-project\venv\Lib\site-packages\rest_framework\views.py", line 469, in handle_exception
    self.raise_uncaught_exception(exc)
    ~~~~~~~~~~~~~~~~~~~~~~~~~~~~~^^^^^
  File "C:\Users\ResTIC16\Documents\cybersec-project\venv\Lib\site-packages\rest_framework\views.py", line 480, in raise_uncaught_exception
    raise exc
  File "C:\Users\ResTIC16\Documents\cybersec-project\venv\Lib\site-packages\rest_framework\views.py", line 506, in dispatch
    response = handler(request, *args, **kwargs)
  File "C:\Users\ResTIC16\Documents\cybersec-project\backend\config\views.py", line 25, in get
    return Response(serializer.data, status=status.HTTP_200_OK)
                    ^^^^^^^^^^^^^^^
  File "C:\Users\ResTIC16\Documents\cybersec-project\venv\Lib\site-packages\rest_framework\serializers.py", line 795, in data
    ret = super().data
          ^^^^^^^^^^^^
  File "C:\Users\ResTIC16\Documents\cybersec-project\venv\Lib\site-packages\rest_framework\serializers.py", line 249, in data
    self._data = self.to_representation(self.instance)
                 ~~~~~~~~~~~~~~~~~~~~~~^^^^^^^^^^^^^^^
  File "C:\Users\ResTIC16\Documents\cybersec-project\venv\Lib\site-packages\rest_framework\serializers.py", line 714, in to_representation
    self.child.to_representation(item) for item in iterable
                                                   ^^^^^^^^
  File "C:\Users\ResTIC16\Documents\cybersec-project\venv\Lib\site-packages\django\db\models\query.py", line 400, in __iter__
    self._fetch_all()
    ~~~~~~~~~~~~~~~^^
  File "C:\Users\ResTIC16\Documents\cybersec-project\venv\Lib\site-packages\django\db\models\query.py", line 1928, in _fetch_all
    self._result_cache = list(self._iterable_class(self))
                         ~~~~^^^^^^^^^^^^^^^^^^^^^^^^^^^^
  File "C:\Users\ResTIC16\Documents\cybersec-project\venv\Lib\site-packages\django\db\models\query.py", line 91, in __iter__
    results = compiler.execute_sql(
        chunked_fetch=self.chunked_fetch, chunk_size=self.chunk_size
    )
  File "C:\Users\ResTIC16\Documents\cybersec-project\venv\Lib\site-packages\django\db\models\sql\compiler.py", line 1574, in execute_sql
    cursor.execute(sql, params)
    ~~~~~~~~~~~~~~^^^^^^^^^^^^^
  File "C:\Users\ResTIC16\Documents\cybersec-project\venv\Lib\site-packages\django\db\backends\utils.py", line 122, in execute
    return super().execute(sql, params)
           ~~~~~~~~~~~~~~~^^^^^^^^^^^^^
  File "C:\Users\ResTIC16\Documents\cybersec-project\venv\Lib\site-packages\django\db\backends\utils.py", line 79, in execute
    return self._execute_with_wrappers(
           ~~~~~~~~~~~~~~~~~~~~~~~~~~~^
        sql, params, many=False, executor=self._execute
        ^^^^^^^^^^^^^^^^^^^^^^^^^^^^^^^^^^^^^^^^^^^^^^^
    )
    ^
  File "C:\Users\ResTIC16\Documents\cybersec-project\venv\Lib\site-packages\django\db\backends\utils.py", line 92, in _execute_with_wrappers
    return executor(sql, params, many, context)
  File "C:\Users\ResTIC16\Documents\cybersec-project\venv\Lib\site-packages\django\db\backends\utils.py", line 100, in _execute
    with self.db.wrap_database_errors:
         ^^^^^^^^^^^^^^^^^^^^^^^^^^^^
  File "C:\Users\ResTIC16\Documents\cybersec-project\venv\Lib\site-packages\django\db\utils.py", line 91, in __exit__
    raise dj_exc_value.with_traceback(traceback) from exc_value
  File "C:\Users\ResTIC16\Documents\cybersec-project\venv\Lib\site-packages\django\db\backends\utils.py", line 105, in _execute
    return self.cursor.execute(sql, params)
           ~~~~~~~~~~~~~~~~~~~^^^^^^^^^^^^^
  File "C:\Users\ResTIC16\Documents\cybersec-project\venv\Lib\site-packages\django\db\backends\sqlite3\base.py", line 354, in execute
    return super().execute(query, params)
           ~~~~~~~~~~~~~~~^^^^^^^^^^^^^^^
django.db.utils.OperationalError: no such table: core_standard
ERROR 2025-02-16 21:50:57,483 log Internal Server Error: /compliance/
Traceback (most recent call last):
  File "C:\Users\ResTIC16\Documents\cybersec-project\venv\Lib\site-packages\django\db\backends\utils.py", line 105, in _execute
    return self.cursor.execute(sql, params)
           ~~~~~~~~~~~~~~~~~~~^^^^^^^^^^^^^
  File "C:\Users\ResTIC16\Documents\cybersec-project\venv\Lib\site-packages\django\db\backends\sqlite3\base.py", line 354, in execute
    return super().execute(query, params)
           ~~~~~~~~~~~~~~~^^^^^^^^^^^^^^^
sqlite3.OperationalError: no such table: core_standard

The above exception was the direct cause of the following exception:

Traceback (most recent call last):
  File "C:\Users\ResTIC16\Documents\cybersec-project\venv\Lib\site-packages\django\core\handlers\exception.py", line 55, in inner
    response = get_response(request)
  File "C:\Users\ResTIC16\Documents\cybersec-project\venv\Lib\site-packages\django\core\handlers\base.py", line 197, in _get_response
    response = wrapped_callback(request, *callback_args, **callback_kwargs)
  File "C:\Users\ResTIC16\Documents\cybersec-project\venv\Lib\site-packages\django\views\decorators\csrf.py", line 65, in _view_wrapper
    return view_func(request, *args, **kwargs)
  File "C:\Users\ResTIC16\Documents\cybersec-project\venv\Lib\site-packages\django\views\generic\base.py", line 104, in view
    return self.dispatch(request, *args, **kwargs)
           ~~~~~~~~~~~~~^^^^^^^^^^^^^^^^^^^^^^^^^^
  File "C:\Users\ResTIC16\Documents\cybersec-project\venv\Lib\site-packages\rest_framework\views.py", line 509, in dispatch
    response = self.handle_exception(exc)
  File "C:\Users\ResTIC16\Documents\cybersec-project\venv\Lib\site-packages\rest_framework\views.py", line 469, in handle_exception
    self.raise_uncaught_exception(exc)
    ~~~~~~~~~~~~~~~~~~~~~~~~~~~~~^^^^^
  File "C:\Users\ResTIC16\Documents\cybersec-project\venv\Lib\site-packages\rest_framework\views.py", line 480, in raise_uncaught_exception
    raise exc
  File "C:\Users\ResTIC16\Documents\cybersec-project\venv\Lib\site-packages\rest_framework\views.py", line 506, in dispatch
    response = handler(request, *args, **kwargs)
  File "C:\Users\ResTIC16\Documents\cybersec-project\backend\config\views.py", line 25, in get
    return Response(serializer.data, status=status.HTTP_200_OK)
                    ^^^^^^^^^^^^^^^
  File "C:\Users\ResTIC16\Documents\cybersec-project\venv\Lib\site-packages\rest_framework\serializers.py", line 795, in data
    ret = super().data
          ^^^^^^^^^^^^
  File "C:\Users\ResTIC16\Documents\cybersec-project\venv\Lib\site-packages\rest_framework\serializers.py", line 249, in data
    self._data = self.to_representation(self.instance)
                 ~~~~~~~~~~~~~~~~~~~~~~^^^^^^^^^^^^^^^
  File "C:\Users\ResTIC16\Documents\cybersec-project\venv\Lib\site-packages\rest_framework\serializers.py", line 714, in to_representation
    self.child.to_representation(item) for item in iterable
                                                   ^^^^^^^^
  File "C:\Users\ResTIC16\Documents\cybersec-project\venv\Lib\site-packages\django\db\models\query.py", line 400, in __iter__
    self._fetch_all()
    ~~~~~~~~~~~~~~~^^
  File "C:\Users\ResTIC16\Documents\cybersec-project\venv\Lib\site-packages\django\db\models\query.py", line 1928, in _fetch_all
    self._result_cache = list(self._iterable_class(self))
                         ~~~~^^^^^^^^^^^^^^^^^^^^^^^^^^^^
  File "C:\Users\ResTIC16\Documents\cybersec-project\venv\Lib\site-packages\django\db\models\query.py", line 91, in __iter__
    results = compiler.execute_sql(
        chunked_fetch=self.chunked_fetch, chunk_size=self.chunk_size
    )
  File "C:\Users\ResTIC16\Documents\cybersec-project\venv\Lib\site-packages\django\db\models\sql\compiler.py", line 1574, in execute_sql
    cursor.execute(sql, params)
    ~~~~~~~~~~~~~~^^^^^^^^^^^^^
  File "C:\Users\ResTIC16\Documents\cybersec-project\venv\Lib\site-packages\django\db\backends\utils.py", line 122, in execute
    return super().execute(sql, params)
           ~~~~~~~~~~~~~~~^^^^^^^^^^^^^
  File "C:\Users\ResTIC16\Documents\cybersec-project\venv\Lib\site-packages\django\db\backends\utils.py", line 79, in execute
    return self._execute_with_wrappers(
           ~~~~~~~~~~~~~~~~~~~~~~~~~~~^
        sql, params, many=False, executor=self._execute
        ^^^^^^^^^^^^^^^^^^^^^^^^^^^^^^^^^^^^^^^^^^^^^^^
    )
    ^
  File "C:\Users\ResTIC16\Documents\cybersec-project\venv\Lib\site-packages\django\db\backends\utils.py", line 92, in _execute_with_wrappers
    return executor(sql, params, many, context)
  File "C:\Users\ResTIC16\Documents\cybersec-project\venv\Lib\site-packages\django\db\backends\utils.py", line 100, in _execute
    with self.db.wrap_database_errors:
         ^^^^^^^^^^^^^^^^^^^^^^^^^^^^
  File "C:\Users\ResTIC16\Documents\cybersec-project\venv\Lib\site-packages\django\db\utils.py", line 91, in __exit__
    raise dj_exc_value.with_traceback(traceback) from exc_value
  File "C:\Users\ResTIC16\Documents\cybersec-project\venv\Lib\site-packages\django\db\backends\utils.py", line 105, in _execute
    return self.cursor.execute(sql, params)
           ~~~~~~~~~~~~~~~~~~~^^^^^^^^^^^^^
  File "C:\Users\ResTIC16\Documents\cybersec-project\venv\Lib\site-packages\django\db\backends\sqlite3\base.py", line 354, in execute
    return super().execute(query, params)
           ~~~~~~~~~~~~~~~^^^^^^^^^^^^^^^
django.db.utils.OperationalError: no such table: core_standard
ERROR 2025-02-16 21:51:20,774 log Internal Server Error: /compliance/
Traceback (most recent call last):
  File "C:\Users\ResTIC16\Documents\cybersec-project\venv\Lib\site-packages\django\db\backends\utils.py", line 105, in _execute
    return self.cursor.execute(sql, params)
           ~~~~~~~~~~~~~~~~~~~^^^^^^^^^^^^^
  File "C:\Users\ResTIC16\Documents\cybersec-project\venv\Lib\site-packages\django\db\backends\sqlite3\base.py", line 354, in execute
    return super().execute(query, params)
           ~~~~~~~~~~~~~~~^^^^^^^^^^^^^^^
sqlite3.OperationalError: no such table: core_standard

The above exception was the direct cause of the following exception:

Traceback (most recent call last):
  File "C:\Users\ResTIC16\Documents\cybersec-project\venv\Lib\site-packages\django\core\handlers\exception.py", line 55, in inner
    response = get_response(request)
  File "C:\Users\ResTIC16\Documents\cybersec-project\venv\Lib\site-packages\django\core\handlers\base.py", line 197, in _get_response
    response = wrapped_callback(request, *callback_args, **callback_kwargs)
  File "C:\Users\ResTIC16\Documents\cybersec-project\venv\Lib\site-packages\django\views\decorators\csrf.py", line 65, in _view_wrapper
    return view_func(request, *args, **kwargs)
  File "C:\Users\ResTIC16\Documents\cybersec-project\venv\Lib\site-packages\django\views\generic\base.py", line 104, in view
    return self.dispatch(request, *args, **kwargs)
           ~~~~~~~~~~~~~^^^^^^^^^^^^^^^^^^^^^^^^^^
  File "C:\Users\ResTIC16\Documents\cybersec-project\venv\Lib\site-packages\rest_framework\views.py", line 509, in dispatch
    response = self.handle_exception(exc)
  File "C:\Users\ResTIC16\Documents\cybersec-project\venv\Lib\site-packages\rest_framework\views.py", line 469, in handle_exception
    self.raise_uncaught_exception(exc)
    ~~~~~~~~~~~~~~~~~~~~~~~~~~~~~^^^^^
  File "C:\Users\ResTIC16\Documents\cybersec-project\venv\Lib\site-packages\rest_framework\views.py", line 480, in raise_uncaught_exception
    raise exc
  File "C:\Users\ResTIC16\Documents\cybersec-project\venv\Lib\site-packages\rest_framework\views.py", line 506, in dispatch
    response = handler(request, *args, **kwargs)
  File "C:\Users\ResTIC16\Documents\cybersec-project\backend\config\views.py", line 25, in get
    return Response(serializer.data, status=status.HTTP_200_OK)
                    ^^^^^^^^^^^^^^^
  File "C:\Users\ResTIC16\Documents\cybersec-project\venv\Lib\site-packages\rest_framework\serializers.py", line 795, in data
    ret = super().data
          ^^^^^^^^^^^^
  File "C:\Users\ResTIC16\Documents\cybersec-project\venv\Lib\site-packages\rest_framework\serializers.py", line 249, in data
    self._data = self.to_representation(self.instance)
                 ~~~~~~~~~~~~~~~~~~~~~~^^^^^^^^^^^^^^^
  File "C:\Users\ResTIC16\Documents\cybersec-project\venv\Lib\site-packages\rest_framework\serializers.py", line 714, in to_representation
    self.child.to_representation(item) for item in iterable
                                                   ^^^^^^^^
  File "C:\Users\ResTIC16\Documents\cybersec-project\venv\Lib\site-packages\django\db\models\query.py", line 400, in __iter__
    self._fetch_all()
    ~~~~~~~~~~~~~~~^^
  File "C:\Users\ResTIC16\Documents\cybersec-project\venv\Lib\site-packages\django\db\models\query.py", line 1928, in _fetch_all
    self._result_cache = list(self._iterable_class(self))
                         ~~~~^^^^^^^^^^^^^^^^^^^^^^^^^^^^
  File "C:\Users\ResTIC16\Documents\cybersec-project\venv\Lib\site-packages\django\db\models\query.py", line 91, in __iter__
    results = compiler.execute_sql(
        chunked_fetch=self.chunked_fetch, chunk_size=self.chunk_size
    )
  File "C:\Users\ResTIC16\Documents\cybersec-project\venv\Lib\site-packages\django\db\models\sql\compiler.py", line 1574, in execute_sql
    cursor.execute(sql, params)
    ~~~~~~~~~~~~~~^^^^^^^^^^^^^
  File "C:\Users\ResTIC16\Documents\cybersec-project\venv\Lib\site-packages\django\db\backends\utils.py", line 122, in execute
    return super().execute(sql, params)
           ~~~~~~~~~~~~~~~^^^^^^^^^^^^^
  File "C:\Users\ResTIC16\Documents\cybersec-project\venv\Lib\site-packages\django\db\backends\utils.py", line 79, in execute
    return self._execute_with_wrappers(
           ~~~~~~~~~~~~~~~~~~~~~~~~~~~^
        sql, params, many=False, executor=self._execute
        ^^^^^^^^^^^^^^^^^^^^^^^^^^^^^^^^^^^^^^^^^^^^^^^
    )
    ^
  File "C:\Users\ResTIC16\Documents\cybersec-project\venv\Lib\site-packages\django\db\backends\utils.py", line 92, in _execute_with_wrappers
    return executor(sql, params, many, context)
  File "C:\Users\ResTIC16\Documents\cybersec-project\venv\Lib\site-packages\django\db\backends\utils.py", line 100, in _execute
    with self.db.wrap_database_errors:
         ^^^^^^^^^^^^^^^^^^^^^^^^^^^^
  File "C:\Users\ResTIC16\Documents\cybersec-project\venv\Lib\site-packages\django\db\utils.py", line 91, in __exit__
    raise dj_exc_value.with_traceback(traceback) from exc_value
  File "C:\Users\ResTIC16\Documents\cybersec-project\venv\Lib\site-packages\django\db\backends\utils.py", line 105, in _execute
    return self.cursor.execute(sql, params)
           ~~~~~~~~~~~~~~~~~~~^^^^^^^^^^^^^
  File "C:\Users\ResTIC16\Documents\cybersec-project\venv\Lib\site-packages\django\db\backends\sqlite3\base.py", line 354, in execute
    return super().execute(query, params)
           ~~~~~~~~~~~~~~~^^^^^^^^^^^^^^^
django.db.utils.OperationalError: no such table: core_standard
ERROR 2025-02-16 21:51:42,099 log Internal Server Error: /compliance/
Traceback (most recent call last):
  File "C:\Users\ResTIC16\Documents\cybersec-project\venv\Lib\site-packages\django\db\backends\utils.py", line 105, in _execute
    return self.cursor.execute(sql, params)
           ~~~~~~~~~~~~~~~~~~~^^^^^^^^^^^^^
  File "C:\Users\ResTIC16\Documents\cybersec-project\venv\Lib\site-packages\django\db\backends\sqlite3\base.py", line 354, in execute
    return super().execute(query, params)
           ~~~~~~~~~~~~~~~^^^^^^^^^^^^^^^
sqlite3.OperationalError: no such table: core_standard

The above exception was the direct cause of the following exception:

Traceback (most recent call last):
  File "C:\Users\ResTIC16\Documents\cybersec-project\venv\Lib\site-packages\django\core\handlers\exception.py", line 55, in inner
    response = get_response(request)
  File "C:\Users\ResTIC16\Documents\cybersec-project\venv\Lib\site-packages\django\core\handlers\base.py", line 197, in _get_response
    response = wrapped_callback(request, *callback_args, **callback_kwargs)
  File "C:\Users\ResTIC16\Documents\cybersec-project\venv\Lib\site-packages\django\views\decorators\csrf.py", line 65, in _view_wrapper
    return view_func(request, *args, **kwargs)
  File "C:\Users\ResTIC16\Documents\cybersec-project\venv\Lib\site-packages\django\views\generic\base.py", line 104, in view
    return self.dispatch(request, *args, **kwargs)
           ~~~~~~~~~~~~~^^^^^^^^^^^^^^^^^^^^^^^^^^
  File "C:\Users\ResTIC16\Documents\cybersec-project\venv\Lib\site-packages\rest_framework\views.py", line 509, in dispatch
    response = self.handle_exception(exc)
  File "C:\Users\ResTIC16\Documents\cybersec-project\venv\Lib\site-packages\rest_framework\views.py", line 469, in handle_exception
    self.raise_uncaught_exception(exc)
    ~~~~~~~~~~~~~~~~~~~~~~~~~~~~~^^^^^
  File "C:\Users\ResTIC16\Documents\cybersec-project\venv\Lib\site-packages\rest_framework\views.py", line 480, in raise_uncaught_exception
    raise exc
  File "C:\Users\ResTIC16\Documents\cybersec-project\venv\Lib\site-packages\rest_framework\views.py", line 506, in dispatch
    response = handler(request, *args, **kwargs)
  File "C:\Users\ResTIC16\Documents\cybersec-project\backend\config\views.py", line 25, in get
    return Response(serializer.data, status=status.HTTP_200_OK)
                    ^^^^^^^^^^^^^^^
  File "C:\Users\ResTIC16\Documents\cybersec-project\venv\Lib\site-packages\rest_framework\serializers.py", line 795, in data
    ret = super().data
          ^^^^^^^^^^^^
  File "C:\Users\ResTIC16\Documents\cybersec-project\venv\Lib\site-packages\rest_framework\serializers.py", line 249, in data
    self._data = self.to_representation(self.instance)
                 ~~~~~~~~~~~~~~~~~~~~~~^^^^^^^^^^^^^^^
  File "C:\Users\ResTIC16\Documents\cybersec-project\venv\Lib\site-packages\rest_framework\serializers.py", line 714, in to_representation
    self.child.to_representation(item) for item in iterable
                                                   ^^^^^^^^
  File "C:\Users\ResTIC16\Documents\cybersec-project\venv\Lib\site-packages\django\db\models\query.py", line 400, in __iter__
    self._fetch_all()
    ~~~~~~~~~~~~~~~^^
  File "C:\Users\ResTIC16\Documents\cybersec-project\venv\Lib\site-packages\django\db\models\query.py", line 1928, in _fetch_all
    self._result_cache = list(self._iterable_class(self))
                         ~~~~^^^^^^^^^^^^^^^^^^^^^^^^^^^^
  File "C:\Users\ResTIC16\Documents\cybersec-project\venv\Lib\site-packages\django\db\models\query.py", line 91, in __iter__
    results = compiler.execute_sql(
        chunked_fetch=self.chunked_fetch, chunk_size=self.chunk_size
    )
  File "C:\Users\ResTIC16\Documents\cybersec-project\venv\Lib\site-packages\django\db\models\sql\compiler.py", line 1574, in execute_sql
    cursor.execute(sql, params)
    ~~~~~~~~~~~~~~^^^^^^^^^^^^^
  File "C:\Users\ResTIC16\Documents\cybersec-project\venv\Lib\site-packages\django\db\backends\utils.py", line 122, in execute
    return super().execute(sql, params)
           ~~~~~~~~~~~~~~~^^^^^^^^^^^^^
  File "C:\Users\ResTIC16\Documents\cybersec-project\venv\Lib\site-packages\django\db\backends\utils.py", line 79, in execute
    return self._execute_with_wrappers(
           ~~~~~~~~~~~~~~~~~~~~~~~~~~~^
        sql, params, many=False, executor=self._execute
        ^^^^^^^^^^^^^^^^^^^^^^^^^^^^^^^^^^^^^^^^^^^^^^^
    )
    ^
  File "C:\Users\ResTIC16\Documents\cybersec-project\venv\Lib\site-packages\django\db\backends\utils.py", line 92, in _execute_with_wrappers
    return executor(sql, params, many, context)
  File "C:\Users\ResTIC16\Documents\cybersec-project\venv\Lib\site-packages\django\db\backends\utils.py", line 100, in _execute
    with self.db.wrap_database_errors:
         ^^^^^^^^^^^^^^^^^^^^^^^^^^^^
  File "C:\Users\ResTIC16\Documents\cybersec-project\venv\Lib\site-packages\django\db\utils.py", line 91, in __exit__
    raise dj_exc_value.with_traceback(traceback) from exc_value
  File "C:\Users\ResTIC16\Documents\cybersec-project\venv\Lib\site-packages\django\db\backends\utils.py", line 105, in _execute
    return self.cursor.execute(sql, params)
           ~~~~~~~~~~~~~~~~~~~^^^^^^^^^^^^^
  File "C:\Users\ResTIC16\Documents\cybersec-project\venv\Lib\site-packages\django\db\backends\sqlite3\base.py", line 354, in execute
    return super().execute(query, params)
           ~~~~~~~~~~~~~~~^^^^^^^^^^^^^^^
django.db.utils.OperationalError: no such table: core_standard
ERROR 2025-02-16 21:52:47,977 log Internal Server Error: /compliance/
Traceback (most recent call last):
  File "C:\Users\ResTIC16\Documents\cybersec-project\venv\Lib\site-packages\django\db\backends\utils.py", line 105, in _execute
    return self.cursor.execute(sql, params)
           ~~~~~~~~~~~~~~~~~~~^^^^^^^^^^^^^
  File "C:\Users\ResTIC16\Documents\cybersec-project\venv\Lib\site-packages\django\db\backends\sqlite3\base.py", line 354, in execute
    return super().execute(query, params)
           ~~~~~~~~~~~~~~~^^^^^^^^^^^^^^^
sqlite3.OperationalError: no such table: core_standard

The above exception was the direct cause of the following exception:

Traceback (most recent call last):
  File "C:\Users\ResTIC16\Documents\cybersec-project\venv\Lib\site-packages\django\core\handlers\exception.py", line 55, in inner
    response = get_response(request)
  File "C:\Users\ResTIC16\Documents\cybersec-project\venv\Lib\site-packages\django\core\handlers\base.py", line 197, in _get_response
    response = wrapped_callback(request, *callback_args, **callback_kwargs)
  File "C:\Users\ResTIC16\Documents\cybersec-project\venv\Lib\site-packages\django\views\decorators\csrf.py", line 65, in _view_wrapper
    return view_func(request, *args, **kwargs)
  File "C:\Users\ResTIC16\Documents\cybersec-project\venv\Lib\site-packages\django\views\generic\base.py", line 104, in view
    return self.dispatch(request, *args, **kwargs)
           ~~~~~~~~~~~~~^^^^^^^^^^^^^^^^^^^^^^^^^^
  File "C:\Users\ResTIC16\Documents\cybersec-project\venv\Lib\site-packages\rest_framework\views.py", line 509, in dispatch
    response = self.handle_exception(exc)
  File "C:\Users\ResTIC16\Documents\cybersec-project\venv\Lib\site-packages\rest_framework\views.py", line 469, in handle_exception
    self.raise_uncaught_exception(exc)
    ~~~~~~~~~~~~~~~~~~~~~~~~~~~~~^^^^^
  File "C:\Users\ResTIC16\Documents\cybersec-project\venv\Lib\site-packages\rest_framework\views.py", line 480, in raise_uncaught_exception
    raise exc
  File "C:\Users\ResTIC16\Documents\cybersec-project\venv\Lib\site-packages\rest_framework\views.py", line 506, in dispatch
    response = handler(request, *args, **kwargs)
  File "C:\Users\ResTIC16\Documents\cybersec-project\backend\config\views.py", line 25, in get
    return Response(serializer.data, status=status.HTTP_200_OK)
                    ^^^^^^^^^^^^^^^
  File "C:\Users\ResTIC16\Documents\cybersec-project\venv\Lib\site-packages\rest_framework\serializers.py", line 795, in data
    ret = super().data
          ^^^^^^^^^^^^
  File "C:\Users\ResTIC16\Documents\cybersec-project\venv\Lib\site-packages\rest_framework\serializers.py", line 249, in data
    self._data = self.to_representation(self.instance)
                 ~~~~~~~~~~~~~~~~~~~~~~^^^^^^^^^^^^^^^
  File "C:\Users\ResTIC16\Documents\cybersec-project\venv\Lib\site-packages\rest_framework\serializers.py", line 714, in to_representation
    self.child.to_representation(item) for item in iterable
                                                   ^^^^^^^^
  File "C:\Users\ResTIC16\Documents\cybersec-project\venv\Lib\site-packages\django\db\models\query.py", line 400, in __iter__
    self._fetch_all()
    ~~~~~~~~~~~~~~~^^
  File "C:\Users\ResTIC16\Documents\cybersec-project\venv\Lib\site-packages\django\db\models\query.py", line 1928, in _fetch_all
    self._result_cache = list(self._iterable_class(self))
                         ~~~~^^^^^^^^^^^^^^^^^^^^^^^^^^^^
  File "C:\Users\ResTIC16\Documents\cybersec-project\venv\Lib\site-packages\django\db\models\query.py", line 91, in __iter__
    results = compiler.execute_sql(
        chunked_fetch=self.chunked_fetch, chunk_size=self.chunk_size
    )
  File "C:\Users\ResTIC16\Documents\cybersec-project\venv\Lib\site-packages\django\db\models\sql\compiler.py", line 1574, in execute_sql
    cursor.execute(sql, params)
    ~~~~~~~~~~~~~~^^^^^^^^^^^^^
  File "C:\Users\ResTIC16\Documents\cybersec-project\venv\Lib\site-packages\django\db\backends\utils.py", line 122, in execute
    return super().execute(sql, params)
           ~~~~~~~~~~~~~~~^^^^^^^^^^^^^
  File "C:\Users\ResTIC16\Documents\cybersec-project\venv\Lib\site-packages\django\db\backends\utils.py", line 79, in execute
    return self._execute_with_wrappers(
           ~~~~~~~~~~~~~~~~~~~~~~~~~~~^
        sql, params, many=False, executor=self._execute
        ^^^^^^^^^^^^^^^^^^^^^^^^^^^^^^^^^^^^^^^^^^^^^^^
    )
    ^
  File "C:\Users\ResTIC16\Documents\cybersec-project\venv\Lib\site-packages\django\db\backends\utils.py", line 92, in _execute_with_wrappers
    return executor(sql, params, many, context)
  File "C:\Users\ResTIC16\Documents\cybersec-project\venv\Lib\site-packages\django\db\backends\utils.py", line 100, in _execute
    with self.db.wrap_database_errors:
         ^^^^^^^^^^^^^^^^^^^^^^^^^^^^
  File "C:\Users\ResTIC16\Documents\cybersec-project\venv\Lib\site-packages\django\db\utils.py", line 91, in __exit__
    raise dj_exc_value.with_traceback(traceback) from exc_value
  File "C:\Users\ResTIC16\Documents\cybersec-project\venv\Lib\site-packages\django\db\backends\utils.py", line 105, in _execute
    return self.cursor.execute(sql, params)
           ~~~~~~~~~~~~~~~~~~~^^^^^^^^^^^^^
  File "C:\Users\ResTIC16\Documents\cybersec-project\venv\Lib\site-packages\django\db\backends\sqlite3\base.py", line 354, in execute
    return super().execute(query, params)
           ~~~~~~~~~~~~~~~^^^^^^^^^^^^^^^
django.db.utils.OperationalError: no such table: core_standard
ERROR 2025-02-16 22:00:23,767 log Internal Server Error: /compliance/
Traceback (most recent call last):
  File "C:\Users\ResTIC16\Documents\cybersec-project\venv\Lib\site-packages\django\db\backends\utils.py", line 105, in _execute
    return self.cursor.execute(sql, params)
           ~~~~~~~~~~~~~~~~~~~^^^^^^^^^^^^^
  File "C:\Users\ResTIC16\Documents\cybersec-project\venv\Lib\site-packages\django\db\backends\sqlite3\base.py", line 354, in execute
    return super().execute(query, params)
           ~~~~~~~~~~~~~~~^^^^^^^^^^^^^^^
sqlite3.OperationalError: no such table: core_standard

The above exception was the direct cause of the following exception:

Traceback (most recent call last):
  File "C:\Users\ResTIC16\Documents\cybersec-project\venv\Lib\site-packages\django\core\handlers\exception.py", line 55, in inner
    response = get_response(request)
  File "C:\Users\ResTIC16\Documents\cybersec-project\venv\Lib\site-packages\django\core\handlers\base.py", line 197, in _get_response
    response = wrapped_callback(request, *callback_args, **callback_kwargs)
  File "C:\Users\ResTIC16\Documents\cybersec-project\venv\Lib\site-packages\django\views\decorators\csrf.py", line 65, in _view_wrapper
    return view_func(request, *args, **kwargs)
  File "C:\Users\ResTIC16\Documents\cybersec-project\venv\Lib\site-packages\django\views\generic\base.py", line 104, in view
    return self.dispatch(request, *args, **kwargs)
           ~~~~~~~~~~~~~^^^^^^^^^^^^^^^^^^^^^^^^^^
  File "C:\Users\ResTIC16\Documents\cybersec-project\venv\Lib\site-packages\rest_framework\views.py", line 509, in dispatch
    response = self.handle_exception(exc)
  File "C:\Users\ResTIC16\Documents\cybersec-project\venv\Lib\site-packages\rest_framework\views.py", line 469, in handle_exception
    self.raise_uncaught_exception(exc)
    ~~~~~~~~~~~~~~~~~~~~~~~~~~~~~^^^^^
  File "C:\Users\ResTIC16\Documents\cybersec-project\venv\Lib\site-packages\rest_framework\views.py", line 480, in raise_uncaught_exception
    raise exc
  File "C:\Users\ResTIC16\Documents\cybersec-project\venv\Lib\site-packages\rest_framework\views.py", line 506, in dispatch
    response = handler(request, *args, **kwargs)
  File "C:\Users\ResTIC16\Documents\cybersec-project\backend\config\views.py", line 25, in get
    return Response(serializer.data, status=status.HTTP_200_OK)
                    ^^^^^^^^^^^^^^^
  File "C:\Users\ResTIC16\Documents\cybersec-project\venv\Lib\site-packages\rest_framework\serializers.py", line 795, in data
    ret = super().data
          ^^^^^^^^^^^^
  File "C:\Users\ResTIC16\Documents\cybersec-project\venv\Lib\site-packages\rest_framework\serializers.py", line 249, in data
    self._data = self.to_representation(self.instance)
                 ~~~~~~~~~~~~~~~~~~~~~~^^^^^^^^^^^^^^^
  File "C:\Users\ResTIC16\Documents\cybersec-project\venv\Lib\site-packages\rest_framework\serializers.py", line 714, in to_representation
    self.child.to_representation(item) for item in iterable
                                                   ^^^^^^^^
  File "C:\Users\ResTIC16\Documents\cybersec-project\venv\Lib\site-packages\django\db\models\query.py", line 400, in __iter__
    self._fetch_all()
    ~~~~~~~~~~~~~~~^^
  File "C:\Users\ResTIC16\Documents\cybersec-project\venv\Lib\site-packages\django\db\models\query.py", line 1928, in _fetch_all
    self._result_cache = list(self._iterable_class(self))
                         ~~~~^^^^^^^^^^^^^^^^^^^^^^^^^^^^
  File "C:\Users\ResTIC16\Documents\cybersec-project\venv\Lib\site-packages\django\db\models\query.py", line 91, in __iter__
    results = compiler.execute_sql(
        chunked_fetch=self.chunked_fetch, chunk_size=self.chunk_size
    )
  File "C:\Users\ResTIC16\Documents\cybersec-project\venv\Lib\site-packages\django\db\models\sql\compiler.py", line 1574, in execute_sql
    cursor.execute(sql, params)
    ~~~~~~~~~~~~~~^^^^^^^^^^^^^
  File "C:\Users\ResTIC16\Documents\cybersec-project\venv\Lib\site-packages\django\db\backends\utils.py", line 122, in execute
    return super().execute(sql, params)
           ~~~~~~~~~~~~~~~^^^^^^^^^^^^^
  File "C:\Users\ResTIC16\Documents\cybersec-project\venv\Lib\site-packages\django\db\backends\utils.py", line 79, in execute
    return self._execute_with_wrappers(
           ~~~~~~~~~~~~~~~~~~~~~~~~~~~^
        sql, params, many=False, executor=self._execute
        ^^^^^^^^^^^^^^^^^^^^^^^^^^^^^^^^^^^^^^^^^^^^^^^
    )
    ^
  File "C:\Users\ResTIC16\Documents\cybersec-project\venv\Lib\site-packages\django\db\backends\utils.py", line 92, in _execute_with_wrappers
    return executor(sql, params, many, context)
  File "C:\Users\ResTIC16\Documents\cybersec-project\venv\Lib\site-packages\django\db\backends\utils.py", line 100, in _execute
    with self.db.wrap_database_errors:
         ^^^^^^^^^^^^^^^^^^^^^^^^^^^^
  File "C:\Users\ResTIC16\Documents\cybersec-project\venv\Lib\site-packages\django\db\utils.py", line 91, in __exit__
    raise dj_exc_value.with_traceback(traceback) from exc_value
  File "C:\Users\ResTIC16\Documents\cybersec-project\venv\Lib\site-packages\django\db\backends\utils.py", line 105, in _execute
    return self.cursor.execute(sql, params)
           ~~~~~~~~~~~~~~~~~~~^^^^^^^^^^^^^
  File "C:\Users\ResTIC16\Documents\cybersec-project\venv\Lib\site-packages\django\db\backends\sqlite3\base.py", line 354, in execute
    return super().execute(query, params)
           ~~~~~~~~~~~~~~~^^^^^^^^^^^^^^^
django.db.utils.OperationalError: no such table: core_standard
ERROR 2025-02-16 22:00:33,569 log Internal Server Error: /compliance/
Traceback (most recent call last):
  File "C:\Users\ResTIC16\Documents\cybersec-project\venv\Lib\site-packages\django\db\backends\utils.py", line 105, in _execute
    return self.cursor.execute(sql, params)
           ~~~~~~~~~~~~~~~~~~~^^^^^^^^^^^^^
  File "C:\Users\ResTIC16\Documents\cybersec-project\venv\Lib\site-packages\django\db\backends\sqlite3\base.py", line 354, in execute
    return super().execute(query, params)
           ~~~~~~~~~~~~~~~^^^^^^^^^^^^^^^
sqlite3.OperationalError: no such table: core_standard

The above exception was the direct cause of the following exception:

Traceback (most recent call last):
  File "C:\Users\ResTIC16\Documents\cybersec-project\venv\Lib\site-packages\django\core\handlers\exception.py", line 55, in inner
    response = get_response(request)
  File "C:\Users\ResTIC16\Documents\cybersec-project\venv\Lib\site-packages\django\core\handlers\base.py", line 197, in _get_response
    response = wrapped_callback(request, *callback_args, **callback_kwargs)
  File "C:\Users\ResTIC16\Documents\cybersec-project\venv\Lib\site-packages\django\views\decorators\csrf.py", line 65, in _view_wrapper
    return view_func(request, *args, **kwargs)
  File "C:\Users\ResTIC16\Documents\cybersec-project\venv\Lib\site-packages\django\views\generic\base.py", line 104, in view
    return self.dispatch(request, *args, **kwargs)
           ~~~~~~~~~~~~~^^^^^^^^^^^^^^^^^^^^^^^^^^
  File "C:\Users\ResTIC16\Documents\cybersec-project\venv\Lib\site-packages\rest_framework\views.py", line 509, in dispatch
    response = self.handle_exception(exc)
  File "C:\Users\ResTIC16\Documents\cybersec-project\venv\Lib\site-packages\rest_framework\views.py", line 469, in handle_exception
    self.raise_uncaught_exception(exc)
    ~~~~~~~~~~~~~~~~~~~~~~~~~~~~~^^^^^
  File "C:\Users\ResTIC16\Documents\cybersec-project\venv\Lib\site-packages\rest_framework\views.py", line 480, in raise_uncaught_exception
    raise exc
  File "C:\Users\ResTIC16\Documents\cybersec-project\venv\Lib\site-packages\rest_framework\views.py", line 506, in dispatch
    response = handler(request, *args, **kwargs)
  File "C:\Users\ResTIC16\Documents\cybersec-project\backend\config\views.py", line 25, in get
    return Response(serializer.data, status=status.HTTP_200_OK)
                    ^^^^^^^^^^^^^^^
  File "C:\Users\ResTIC16\Documents\cybersec-project\venv\Lib\site-packages\rest_framework\serializers.py", line 795, in data
    ret = super().data
          ^^^^^^^^^^^^
  File "C:\Users\ResTIC16\Documents\cybersec-project\venv\Lib\site-packages\rest_framework\serializers.py", line 249, in data
    self._data = self.to_representation(self.instance)
                 ~~~~~~~~~~~~~~~~~~~~~~^^^^^^^^^^^^^^^
  File "C:\Users\ResTIC16\Documents\cybersec-project\venv\Lib\site-packages\rest_framework\serializers.py", line 714, in to_representation
    self.child.to_representation(item) for item in iterable
                                                   ^^^^^^^^
  File "C:\Users\ResTIC16\Documents\cybersec-project\venv\Lib\site-packages\django\db\models\query.py", line 400, in __iter__
    self._fetch_all()
    ~~~~~~~~~~~~~~~^^
  File "C:\Users\ResTIC16\Documents\cybersec-project\venv\Lib\site-packages\django\db\models\query.py", line 1928, in _fetch_all
    self._result_cache = list(self._iterable_class(self))
                         ~~~~^^^^^^^^^^^^^^^^^^^^^^^^^^^^
  File "C:\Users\ResTIC16\Documents\cybersec-project\venv\Lib\site-packages\django\db\models\query.py", line 91, in __iter__
    results = compiler.execute_sql(
        chunked_fetch=self.chunked_fetch, chunk_size=self.chunk_size
    )
  File "C:\Users\ResTIC16\Documents\cybersec-project\venv\Lib\site-packages\django\db\models\sql\compiler.py", line 1574, in execute_sql
    cursor.execute(sql, params)
    ~~~~~~~~~~~~~~^^^^^^^^^^^^^
  File "C:\Users\ResTIC16\Documents\cybersec-project\venv\Lib\site-packages\django\db\backends\utils.py", line 122, in execute
    return super().execute(sql, params)
           ~~~~~~~~~~~~~~~^^^^^^^^^^^^^
  File "C:\Users\ResTIC16\Documents\cybersec-project\venv\Lib\site-packages\django\db\backends\utils.py", line 79, in execute
    return self._execute_with_wrappers(
           ~~~~~~~~~~~~~~~~~~~~~~~~~~~^
        sql, params, many=False, executor=self._execute
        ^^^^^^^^^^^^^^^^^^^^^^^^^^^^^^^^^^^^^^^^^^^^^^^
    )
    ^
  File "C:\Users\ResTIC16\Documents\cybersec-project\venv\Lib\site-packages\django\db\backends\utils.py", line 92, in _execute_with_wrappers
    return executor(sql, params, many, context)
  File "C:\Users\ResTIC16\Documents\cybersec-project\venv\Lib\site-packages\django\db\backends\utils.py", line 100, in _execute
    with self.db.wrap_database_errors:
         ^^^^^^^^^^^^^^^^^^^^^^^^^^^^
  File "C:\Users\ResTIC16\Documents\cybersec-project\venv\Lib\site-packages\django\db\utils.py", line 91, in __exit__
    raise dj_exc_value.with_traceback(traceback) from exc_value
  File "C:\Users\ResTIC16\Documents\cybersec-project\venv\Lib\site-packages\django\db\backends\utils.py", line 105, in _execute
    return self.cursor.execute(sql, params)
           ~~~~~~~~~~~~~~~~~~~^^^^^^^^^^^^^
  File "C:\Users\ResTIC16\Documents\cybersec-project\venv\Lib\site-packages\django\db\backends\sqlite3\base.py", line 354, in execute
    return super().execute(query, params)
           ~~~~~~~~~~~~~~~^^^^^^^^^^^^^^^
django.db.utils.OperationalError: no such table: core_standard
ERROR 2025-02-17 17:28:30,648 log Internal Server Error: /compliance/
Traceback (most recent call last):
  File "C:\Users\ResTIC16\Documents\cybersec-project\venv\Lib\site-packages\django\db\backends\utils.py", line 105, in _execute
    return self.cursor.execute(sql, params)
           ~~~~~~~~~~~~~~~~~~~^^^^^^^^^^^^^
  File "C:\Users\ResTIC16\Documents\cybersec-project\venv\Lib\site-packages\django\db\backends\sqlite3\base.py", line 354, in execute
    return super().execute(query, params)
           ~~~~~~~~~~~~~~~^^^^^^^^^^^^^^^
sqlite3.OperationalError: no such table: core_standard

The above exception was the direct cause of the following exception:

Traceback (most recent call last):
  File "C:\Users\ResTIC16\Documents\cybersec-project\venv\Lib\site-packages\django\core\handlers\exception.py", line 55, in inner
    response = get_response(request)
  File "C:\Users\ResTIC16\Documents\cybersec-project\venv\Lib\site-packages\django\core\handlers\base.py", line 197, in _get_response
    response = wrapped_callback(request, *callback_args, **callback_kwargs)
  File "C:\Users\ResTIC16\Documents\cybersec-project\venv\Lib\site-packages\django\views\decorators\csrf.py", line 65, in _view_wrapper
    return view_func(request, *args, **kwargs)
  File "C:\Users\ResTIC16\Documents\cybersec-project\venv\Lib\site-packages\django\views\generic\base.py", line 104, in view
    return self.dispatch(request, *args, **kwargs)
           ~~~~~~~~~~~~~^^^^^^^^^^^^^^^^^^^^^^^^^^
  File "C:\Users\ResTIC16\Documents\cybersec-project\venv\Lib\site-packages\rest_framework\views.py", line 509, in dispatch
    response = self.handle_exception(exc)
  File "C:\Users\ResTIC16\Documents\cybersec-project\venv\Lib\site-packages\rest_framework\views.py", line 469, in handle_exception
    self.raise_uncaught_exception(exc)
    ~~~~~~~~~~~~~~~~~~~~~~~~~~~~~^^^^^
  File "C:\Users\ResTIC16\Documents\cybersec-project\venv\Lib\site-packages\rest_framework\views.py", line 480, in raise_uncaught_exception
    raise exc
  File "C:\Users\ResTIC16\Documents\cybersec-project\venv\Lib\site-packages\rest_framework\views.py", line 506, in dispatch
    response = handler(request, *args, **kwargs)
  File "C:\Users\ResTIC16\Documents\cybersec-project\backend\config\views.py", line 25, in get
    return Response(serializer.data, status=status.HTTP_200_OK)
                    ^^^^^^^^^^^^^^^
  File "C:\Users\ResTIC16\Documents\cybersec-project\venv\Lib\site-packages\rest_framework\serializers.py", line 795, in data
    ret = super().data
          ^^^^^^^^^^^^
  File "C:\Users\ResTIC16\Documents\cybersec-project\venv\Lib\site-packages\rest_framework\serializers.py", line 249, in data
    self._data = self.to_representation(self.instance)
                 ~~~~~~~~~~~~~~~~~~~~~~^^^^^^^^^^^^^^^
  File "C:\Users\ResTIC16\Documents\cybersec-project\venv\Lib\site-packages\rest_framework\serializers.py", line 714, in to_representation
    self.child.to_representation(item) for item in iterable
                                                   ^^^^^^^^
  File "C:\Users\ResTIC16\Documents\cybersec-project\venv\Lib\site-packages\django\db\models\query.py", line 400, in __iter__
    self._fetch_all()
    ~~~~~~~~~~~~~~~^^
  File "C:\Users\ResTIC16\Documents\cybersec-project\venv\Lib\site-packages\django\db\models\query.py", line 1928, in _fetch_all
    self._result_cache = list(self._iterable_class(self))
                         ~~~~^^^^^^^^^^^^^^^^^^^^^^^^^^^^
  File "C:\Users\ResTIC16\Documents\cybersec-project\venv\Lib\site-packages\django\db\models\query.py", line 91, in __iter__
    results = compiler.execute_sql(
        chunked_fetch=self.chunked_fetch, chunk_size=self.chunk_size
    )
  File "C:\Users\ResTIC16\Documents\cybersec-project\venv\Lib\site-packages\django\db\models\sql\compiler.py", line 1574, in execute_sql
    cursor.execute(sql, params)
    ~~~~~~~~~~~~~~^^^^^^^^^^^^^
  File "C:\Users\ResTIC16\Documents\cybersec-project\venv\Lib\site-packages\django\db\backends\utils.py", line 122, in execute
    return super().execute(sql, params)
           ~~~~~~~~~~~~~~~^^^^^^^^^^^^^
  File "C:\Users\ResTIC16\Documents\cybersec-project\venv\Lib\site-packages\django\db\backends\utils.py", line 79, in execute
    return self._execute_with_wrappers(
           ~~~~~~~~~~~~~~~~~~~~~~~~~~~^
        sql, params, many=False, executor=self._execute
        ^^^^^^^^^^^^^^^^^^^^^^^^^^^^^^^^^^^^^^^^^^^^^^^
    )
    ^
  File "C:\Users\ResTIC16\Documents\cybersec-project\venv\Lib\site-packages\django\db\backends\utils.py", line 92, in _execute_with_wrappers
    return executor(sql, params, many, context)
  File "C:\Users\ResTIC16\Documents\cybersec-project\venv\Lib\site-packages\django\db\backends\utils.py", line 100, in _execute
    with self.db.wrap_database_errors:
         ^^^^^^^^^^^^^^^^^^^^^^^^^^^^
  File "C:\Users\ResTIC16\Documents\cybersec-project\venv\Lib\site-packages\django\db\utils.py", line 91, in __exit__
    raise dj_exc_value.with_traceback(traceback) from exc_value
  File "C:\Users\ResTIC16\Documents\cybersec-project\venv\Lib\site-packages\django\db\backends\utils.py", line 105, in _execute
    return self.cursor.execute(sql, params)
           ~~~~~~~~~~~~~~~~~~~^^^^^^^^^^^^^
  File "C:\Users\ResTIC16\Documents\cybersec-project\venv\Lib\site-packages\django\db\backends\sqlite3\base.py", line 354, in execute
    return super().execute(query, params)
           ~~~~~~~~~~~~~~~^^^^^^^^^^^^^^^
django.db.utils.OperationalError: no such table: core_standard
ERROR 2025-02-17 22:31:13,684 log Internal Server Error: /compliance/
Traceback (most recent call last):
  File "C:\Users\ResTIC16\Documents\cybersec-project\venv\Lib\site-packages\django\db\backends\utils.py", line 105, in _execute
    return self.cursor.execute(sql, params)
           ~~~~~~~~~~~~~~~~~~~^^^^^^^^^^^^^
  File "C:\Users\ResTIC16\Documents\cybersec-project\venv\Lib\site-packages\django\db\backends\sqlite3\base.py", line 354, in execute
    return super().execute(query, params)
           ~~~~~~~~~~~~~~~^^^^^^^^^^^^^^^
sqlite3.OperationalError: no such table: core_standard

The above exception was the direct cause of the following exception:

Traceback (most recent call last):
  File "C:\Users\ResTIC16\Documents\cybersec-project\venv\Lib\site-packages\django\core\handlers\exception.py", line 55, in inner
    response = get_response(request)
  File "C:\Users\ResTIC16\Documents\cybersec-project\venv\Lib\site-packages\django\core\handlers\base.py", line 197, in _get_response
    response = wrapped_callback(request, *callback_args, **callback_kwargs)
  File "C:\Users\ResTIC16\Documents\cybersec-project\venv\Lib\site-packages\django\views\decorators\csrf.py", line 65, in _view_wrapper
    return view_func(request, *args, **kwargs)
  File "C:\Users\ResTIC16\Documents\cybersec-project\venv\Lib\site-packages\django\views\generic\base.py", line 104, in view
    return self.dispatch(request, *args, **kwargs)
           ~~~~~~~~~~~~~^^^^^^^^^^^^^^^^^^^^^^^^^^
  File "C:\Users\ResTIC16\Documents\cybersec-project\venv\Lib\site-packages\rest_framework\views.py", line 509, in dispatch
    response = self.handle_exception(exc)
  File "C:\Users\ResTIC16\Documents\cybersec-project\venv\Lib\site-packages\rest_framework\views.py", line 469, in handle_exception
    self.raise_uncaught_exception(exc)
    ~~~~~~~~~~~~~~~~~~~~~~~~~~~~~^^^^^
  File "C:\Users\ResTIC16\Documents\cybersec-project\venv\Lib\site-packages\rest_framework\views.py", line 480, in raise_uncaught_exception
    raise exc
  File "C:\Users\ResTIC16\Documents\cybersec-project\venv\Lib\site-packages\rest_framework\views.py", line 506, in dispatch
    response = handler(request, *args, **kwargs)
  File "C:\Users\ResTIC16\Documents\cybersec-project\backend\config\views.py", line 22, in get
    return Response(serializer.data, status=status.HTTP_200_OK)
                    ^^^^^^^^^^^^^^^
  File "C:\Users\ResTIC16\Documents\cybersec-project\venv\Lib\site-packages\rest_framework\serializers.py", line 795, in data
    ret = super().data
          ^^^^^^^^^^^^
  File "C:\Users\ResTIC16\Documents\cybersec-project\venv\Lib\site-packages\rest_framework\serializers.py", line 249, in data
    self._data = self.to_representation(self.instance)
                 ~~~~~~~~~~~~~~~~~~~~~~^^^^^^^^^^^^^^^
  File "C:\Users\ResTIC16\Documents\cybersec-project\venv\Lib\site-packages\rest_framework\serializers.py", line 714, in to_representation
    self.child.to_representation(item) for item in iterable
                                                   ^^^^^^^^
  File "C:\Users\ResTIC16\Documents\cybersec-project\venv\Lib\site-packages\django\db\models\query.py", line 400, in __iter__
    self._fetch_all()
    ~~~~~~~~~~~~~~~^^
  File "C:\Users\ResTIC16\Documents\cybersec-project\venv\Lib\site-packages\django\db\models\query.py", line 1928, in _fetch_all
    self._result_cache = list(self._iterable_class(self))
                         ~~~~^^^^^^^^^^^^^^^^^^^^^^^^^^^^
  File "C:\Users\ResTIC16\Documents\cybersec-project\venv\Lib\site-packages\django\db\models\query.py", line 91, in __iter__
    results = compiler.execute_sql(
        chunked_fetch=self.chunked_fetch, chunk_size=self.chunk_size
    )
  File "C:\Users\ResTIC16\Documents\cybersec-project\venv\Lib\site-packages\django\db\models\sql\compiler.py", line 1574, in execute_sql
    cursor.execute(sql, params)
    ~~~~~~~~~~~~~~^^^^^^^^^^^^^
  File "C:\Users\ResTIC16\Documents\cybersec-project\venv\Lib\site-packages\django\db\backends\utils.py", line 122, in execute
    return super().execute(sql, params)
           ~~~~~~~~~~~~~~~^^^^^^^^^^^^^
  File "C:\Users\ResTIC16\Documents\cybersec-project\venv\Lib\site-packages\django\db\backends\utils.py", line 79, in execute
    return self._execute_with_wrappers(
           ~~~~~~~~~~~~~~~~~~~~~~~~~~~^
        sql, params, many=False, executor=self._execute
        ^^^^^^^^^^^^^^^^^^^^^^^^^^^^^^^^^^^^^^^^^^^^^^^
    )
    ^
  File "C:\Users\ResTIC16\Documents\cybersec-project\venv\Lib\site-packages\django\db\backends\utils.py", line 92, in _execute_with_wrappers
    return executor(sql, params, many, context)
  File "C:\Users\ResTIC16\Documents\cybersec-project\venv\Lib\site-packages\django\db\backends\utils.py", line 100, in _execute
    with self.db.wrap_database_errors:
         ^^^^^^^^^^^^^^^^^^^^^^^^^^^^
  File "C:\Users\ResTIC16\Documents\cybersec-project\venv\Lib\site-packages\django\db\utils.py", line 91, in __exit__
    raise dj_exc_value.with_traceback(traceback) from exc_value
  File "C:\Users\ResTIC16\Documents\cybersec-project\venv\Lib\site-packages\django\db\backends\utils.py", line 105, in _execute
    return self.cursor.execute(sql, params)
           ~~~~~~~~~~~~~~~~~~~^^^^^^^^^^^^^
  File "C:\Users\ResTIC16\Documents\cybersec-project\venv\Lib\site-packages\django\db\backends\sqlite3\base.py", line 354, in execute
    return super().execute(query, params)
           ~~~~~~~~~~~~~~~^^^^^^^^^^^^^^^
django.db.utils.OperationalError: no such table: core_standard
ERROR 2025-02-17 22:31:36,503 log Internal Server Error: /compliance/
Traceback (most recent call last):
  File "C:\Users\ResTIC16\Documents\cybersec-project\venv\Lib\site-packages\django\db\backends\utils.py", line 105, in _execute
    return self.cursor.execute(sql, params)
           ~~~~~~~~~~~~~~~~~~~^^^^^^^^^^^^^
  File "C:\Users\ResTIC16\Documents\cybersec-project\venv\Lib\site-packages\django\db\backends\sqlite3\base.py", line 354, in execute
    return super().execute(query, params)
           ~~~~~~~~~~~~~~~^^^^^^^^^^^^^^^
sqlite3.OperationalError: no such table: core_standard

The above exception was the direct cause of the following exception:

Traceback (most recent call last):
  File "C:\Users\ResTIC16\Documents\cybersec-project\venv\Lib\site-packages\django\core\handlers\exception.py", line 55, in inner
    response = get_response(request)
  File "C:\Users\ResTIC16\Documents\cybersec-project\venv\Lib\site-packages\django\core\handlers\base.py", line 197, in _get_response
    response = wrapped_callback(request, *callback_args, **callback_kwargs)
  File "C:\Users\ResTIC16\Documents\cybersec-project\venv\Lib\site-packages\django\views\decorators\csrf.py", line 65, in _view_wrapper
    return view_func(request, *args, **kwargs)
  File "C:\Users\ResTIC16\Documents\cybersec-project\venv\Lib\site-packages\django\views\generic\base.py", line 104, in view
    return self.dispatch(request, *args, **kwargs)
           ~~~~~~~~~~~~~^^^^^^^^^^^^^^^^^^^^^^^^^^
  File "C:\Users\ResTIC16\Documents\cybersec-project\venv\Lib\site-packages\rest_framework\views.py", line 509, in dispatch
    response = self.handle_exception(exc)
  File "C:\Users\ResTIC16\Documents\cybersec-project\venv\Lib\site-packages\rest_framework\views.py", line 469, in handle_exception
    self.raise_uncaught_exception(exc)
    ~~~~~~~~~~~~~~~~~~~~~~~~~~~~~^^^^^
  File "C:\Users\ResTIC16\Documents\cybersec-project\venv\Lib\site-packages\rest_framework\views.py", line 480, in raise_uncaught_exception
    raise exc
  File "C:\Users\ResTIC16\Documents\cybersec-project\venv\Lib\site-packages\rest_framework\views.py", line 506, in dispatch
    response = handler(request, *args, **kwargs)
  File "C:\Users\ResTIC16\Documents\cybersec-project\backend\config\views.py", line 22, in get
    return Response(serializer.data, status=status.HTTP_200_OK)
                    ^^^^^^^^^^^^^^^
  File "C:\Users\ResTIC16\Documents\cybersec-project\venv\Lib\site-packages\rest_framework\serializers.py", line 795, in data
    ret = super().data
          ^^^^^^^^^^^^
  File "C:\Users\ResTIC16\Documents\cybersec-project\venv\Lib\site-packages\rest_framework\serializers.py", line 249, in data
    self._data = self.to_representation(self.instance)
                 ~~~~~~~~~~~~~~~~~~~~~~^^^^^^^^^^^^^^^
  File "C:\Users\ResTIC16\Documents\cybersec-project\venv\Lib\site-packages\rest_framework\serializers.py", line 714, in to_representation
    self.child.to_representation(item) for item in iterable
                                                   ^^^^^^^^
  File "C:\Users\ResTIC16\Documents\cybersec-project\venv\Lib\site-packages\django\db\models\query.py", line 400, in __iter__
    self._fetch_all()
    ~~~~~~~~~~~~~~~^^
  File "C:\Users\ResTIC16\Documents\cybersec-project\venv\Lib\site-packages\django\db\models\query.py", line 1928, in _fetch_all
    self._result_cache = list(self._iterable_class(self))
                         ~~~~^^^^^^^^^^^^^^^^^^^^^^^^^^^^
  File "C:\Users\ResTIC16\Documents\cybersec-project\venv\Lib\site-packages\django\db\models\query.py", line 91, in __iter__
    results = compiler.execute_sql(
        chunked_fetch=self.chunked_fetch, chunk_size=self.chunk_size
    )
  File "C:\Users\ResTIC16\Documents\cybersec-project\venv\Lib\site-packages\django\db\models\sql\compiler.py", line 1574, in execute_sql
    cursor.execute(sql, params)
    ~~~~~~~~~~~~~~^^^^^^^^^^^^^
  File "C:\Users\ResTIC16\Documents\cybersec-project\venv\Lib\site-packages\django\db\backends\utils.py", line 122, in execute
    return super().execute(sql, params)
           ~~~~~~~~~~~~~~~^^^^^^^^^^^^^
  File "C:\Users\ResTIC16\Documents\cybersec-project\venv\Lib\site-packages\django\db\backends\utils.py", line 79, in execute
    return self._execute_with_wrappers(
           ~~~~~~~~~~~~~~~~~~~~~~~~~~~^
        sql, params, many=False, executor=self._execute
        ^^^^^^^^^^^^^^^^^^^^^^^^^^^^^^^^^^^^^^^^^^^^^^^
    )
    ^
  File "C:\Users\ResTIC16\Documents\cybersec-project\venv\Lib\site-packages\django\db\backends\utils.py", line 92, in _execute_with_wrappers
    return executor(sql, params, many, context)
  File "C:\Users\ResTIC16\Documents\cybersec-project\venv\Lib\site-packages\django\db\backends\utils.py", line 100, in _execute
    with self.db.wrap_database_errors:
         ^^^^^^^^^^^^^^^^^^^^^^^^^^^^
  File "C:\Users\ResTIC16\Documents\cybersec-project\venv\Lib\site-packages\django\db\utils.py", line 91, in __exit__
    raise dj_exc_value.with_traceback(traceback) from exc_value
  File "C:\Users\ResTIC16\Documents\cybersec-project\venv\Lib\site-packages\django\db\backends\utils.py", line 105, in _execute
    return self.cursor.execute(sql, params)
           ~~~~~~~~~~~~~~~~~~~^^^^^^^^^^^^^
  File "C:\Users\ResTIC16\Documents\cybersec-project\venv\Lib\site-packages\django\db\backends\sqlite3\base.py", line 354, in execute
    return super().execute(query, params)
           ~~~~~~~~~~~~~~~^^^^^^^^^^^^^^^
django.db.utils.OperationalError: no such table: core_standard
ERROR 2025-02-18 09:29:11,110 log Internal Server Error: /compliance/
Traceback (most recent call last):
  File "C:\Users\ResTIC16\Documents\cybersec-project\venv\Lib\site-packages\django\db\backends\utils.py", line 105, in _execute
    return self.cursor.execute(sql, params)
           ~~~~~~~~~~~~~~~~~~~^^^^^^^^^^^^^
  File "C:\Users\ResTIC16\Documents\cybersec-project\venv\Lib\site-packages\django\db\backends\sqlite3\base.py", line 354, in execute
    return super().execute(query, params)
           ~~~~~~~~~~~~~~~^^^^^^^^^^^^^^^
sqlite3.OperationalError: no such table: core_standard

The above exception was the direct cause of the following exception:

Traceback (most recent call last):
  File "C:\Users\ResTIC16\Documents\cybersec-project\venv\Lib\site-packages\django\core\handlers\exception.py", line 55, in inner
    response = get_response(request)
  File "C:\Users\ResTIC16\Documents\cybersec-project\venv\Lib\site-packages\django\core\handlers\base.py", line 197, in _get_response
    response = wrapped_callback(request, *callback_args, **callback_kwargs)
  File "C:\Users\ResTIC16\Documents\cybersec-project\venv\Lib\site-packages\django\views\decorators\csrf.py", line 65, in _view_wrapper
    return view_func(request, *args, **kwargs)
  File "C:\Users\ResTIC16\Documents\cybersec-project\venv\Lib\site-packages\django\views\generic\base.py", line 104, in view
    return self.dispatch(request, *args, **kwargs)
           ~~~~~~~~~~~~~^^^^^^^^^^^^^^^^^^^^^^^^^^
  File "C:\Users\ResTIC16\Documents\cybersec-project\venv\Lib\site-packages\rest_framework\views.py", line 509, in dispatch
    response = self.handle_exception(exc)
  File "C:\Users\ResTIC16\Documents\cybersec-project\venv\Lib\site-packages\rest_framework\views.py", line 469, in handle_exception
    self.raise_uncaught_exception(exc)
    ~~~~~~~~~~~~~~~~~~~~~~~~~~~~~^^^^^
  File "C:\Users\ResTIC16\Documents\cybersec-project\venv\Lib\site-packages\rest_framework\views.py", line 480, in raise_uncaught_exception
    raise exc
  File "C:\Users\ResTIC16\Documents\cybersec-project\venv\Lib\site-packages\rest_framework\views.py", line 506, in dispatch
    response = handler(request, *args, **kwargs)
  File "C:\Users\ResTIC16\Documents\cybersec-project\backend\config\views.py", line 22, in get
    return Response(serializer.data, status=status.HTTP_200_OK)
                    ^^^^^^^^^^^^^^^
  File "C:\Users\ResTIC16\Documents\cybersec-project\venv\Lib\site-packages\rest_framework\serializers.py", line 795, in data
    ret = super().data
          ^^^^^^^^^^^^
  File "C:\Users\ResTIC16\Documents\cybersec-project\venv\Lib\site-packages\rest_framework\serializers.py", line 249, in data
    self._data = self.to_representation(self.instance)
                 ~~~~~~~~~~~~~~~~~~~~~~^^^^^^^^^^^^^^^
  File "C:\Users\ResTIC16\Documents\cybersec-project\venv\Lib\site-packages\rest_framework\serializers.py", line 714, in to_representation
    self.child.to_representation(item) for item in iterable
                                                   ^^^^^^^^
  File "C:\Users\ResTIC16\Documents\cybersec-project\venv\Lib\site-packages\django\db\models\query.py", line 400, in __iter__
    self._fetch_all()
    ~~~~~~~~~~~~~~~^^
  File "C:\Users\ResTIC16\Documents\cybersec-project\venv\Lib\site-packages\django\db\models\query.py", line 1928, in _fetch_all
    self._result_cache = list(self._iterable_class(self))
                         ~~~~^^^^^^^^^^^^^^^^^^^^^^^^^^^^
  File "C:\Users\ResTIC16\Documents\cybersec-project\venv\Lib\site-packages\django\db\models\query.py", line 91, in __iter__
    results = compiler.execute_sql(
        chunked_fetch=self.chunked_fetch, chunk_size=self.chunk_size
    )
  File "C:\Users\ResTIC16\Documents\cybersec-project\venv\Lib\site-packages\django\db\models\sql\compiler.py", line 1574, in execute_sql
    cursor.execute(sql, params)
    ~~~~~~~~~~~~~~^^^^^^^^^^^^^
  File "C:\Users\ResTIC16\Documents\cybersec-project\venv\Lib\site-packages\django\db\backends\utils.py", line 122, in execute
    return super().execute(sql, params)
           ~~~~~~~~~~~~~~~^^^^^^^^^^^^^
  File "C:\Users\ResTIC16\Documents\cybersec-project\venv\Lib\site-packages\django\db\backends\utils.py", line 79, in execute
    return self._execute_with_wrappers(
           ~~~~~~~~~~~~~~~~~~~~~~~~~~~^
        sql, params, many=False, executor=self._execute
        ^^^^^^^^^^^^^^^^^^^^^^^^^^^^^^^^^^^^^^^^^^^^^^^
    )
    ^
  File "C:\Users\ResTIC16\Documents\cybersec-project\venv\Lib\site-packages\django\db\backends\utils.py", line 92, in _execute_with_wrappers
    return executor(sql, params, many, context)
  File "C:\Users\ResTIC16\Documents\cybersec-project\venv\Lib\site-packages\django\db\backends\utils.py", line 100, in _execute
    with self.db.wrap_database_errors:
         ^^^^^^^^^^^^^^^^^^^^^^^^^^^^
  File "C:\Users\ResTIC16\Documents\cybersec-project\venv\Lib\site-packages\django\db\utils.py", line 91, in __exit__
    raise dj_exc_value.with_traceback(traceback) from exc_value
  File "C:\Users\ResTIC16\Documents\cybersec-project\venv\Lib\site-packages\django\db\backends\utils.py", line 105, in _execute
    return self.cursor.execute(sql, params)
           ~~~~~~~~~~~~~~~~~~~^^^^^^^^^^^^^
  File "C:\Users\ResTIC16\Documents\cybersec-project\venv\Lib\site-packages\django\db\backends\sqlite3\base.py", line 354, in execute
    return super().execute(query, params)
           ~~~~~~~~~~~~~~~^^^^^^^^^^^^^^^
django.db.utils.OperationalError: no such table: core_standard
ERROR 2025-02-18 09:33:15,688 log Internal Server Error: /compliance/
Traceback (most recent call last):
  File "C:\Users\ResTIC16\Documents\cybersec-project\venv\Lib\site-packages\django\db\backends\utils.py", line 105, in _execute
    return self.cursor.execute(sql, params)
           ~~~~~~~~~~~~~~~~~~~^^^^^^^^^^^^^
  File "C:\Users\ResTIC16\Documents\cybersec-project\venv\Lib\site-packages\django\db\backends\sqlite3\base.py", line 354, in execute
    return super().execute(query, params)
           ~~~~~~~~~~~~~~~^^^^^^^^^^^^^^^
sqlite3.OperationalError: no such table: core_standard

The above exception was the direct cause of the following exception:

Traceback (most recent call last):
  File "C:\Users\ResTIC16\Documents\cybersec-project\venv\Lib\site-packages\django\core\handlers\exception.py", line 55, in inner
    response = get_response(request)
  File "C:\Users\ResTIC16\Documents\cybersec-project\venv\Lib\site-packages\django\core\handlers\base.py", line 197, in _get_response
    response = wrapped_callback(request, *callback_args, **callback_kwargs)
  File "C:\Users\ResTIC16\Documents\cybersec-project\venv\Lib\site-packages\django\views\decorators\csrf.py", line 65, in _view_wrapper
    return view_func(request, *args, **kwargs)
  File "C:\Users\ResTIC16\Documents\cybersec-project\venv\Lib\site-packages\django\views\generic\base.py", line 104, in view
    return self.dispatch(request, *args, **kwargs)
           ~~~~~~~~~~~~~^^^^^^^^^^^^^^^^^^^^^^^^^^
  File "C:\Users\ResTIC16\Documents\cybersec-project\venv\Lib\site-packages\rest_framework\views.py", line 509, in dispatch
    response = self.handle_exception(exc)
  File "C:\Users\ResTIC16\Documents\cybersec-project\venv\Lib\site-packages\rest_framework\views.py", line 469, in handle_exception
    self.raise_uncaught_exception(exc)
    ~~~~~~~~~~~~~~~~~~~~~~~~~~~~~^^^^^
  File "C:\Users\ResTIC16\Documents\cybersec-project\venv\Lib\site-packages\rest_framework\views.py", line 480, in raise_uncaught_exception
    raise exc
  File "C:\Users\ResTIC16\Documents\cybersec-project\venv\Lib\site-packages\rest_framework\views.py", line 506, in dispatch
    response = handler(request, *args, **kwargs)
  File "C:\Users\ResTIC16\Documents\cybersec-project\backend\config\views.py", line 22, in get
    return Response(serializer.data, status=status.HTTP_200_OK)
                    ^^^^^^^^^^^^^^^
  File "C:\Users\ResTIC16\Documents\cybersec-project\venv\Lib\site-packages\rest_framework\serializers.py", line 795, in data
    ret = super().data
          ^^^^^^^^^^^^
  File "C:\Users\ResTIC16\Documents\cybersec-project\venv\Lib\site-packages\rest_framework\serializers.py", line 249, in data
    self._data = self.to_representation(self.instance)
                 ~~~~~~~~~~~~~~~~~~~~~~^^^^^^^^^^^^^^^
  File "C:\Users\ResTIC16\Documents\cybersec-project\venv\Lib\site-packages\rest_framework\serializers.py", line 714, in to_representation
    self.child.to_representation(item) for item in iterable
                                                   ^^^^^^^^
  File "C:\Users\ResTIC16\Documents\cybersec-project\venv\Lib\site-packages\django\db\models\query.py", line 400, in __iter__
    self._fetch_all()
    ~~~~~~~~~~~~~~~^^
  File "C:\Users\ResTIC16\Documents\cybersec-project\venv\Lib\site-packages\django\db\models\query.py", line 1928, in _fetch_all
    self._result_cache = list(self._iterable_class(self))
                         ~~~~^^^^^^^^^^^^^^^^^^^^^^^^^^^^
  File "C:\Users\ResTIC16\Documents\cybersec-project\venv\Lib\site-packages\django\db\models\query.py", line 91, in __iter__
    results = compiler.execute_sql(
        chunked_fetch=self.chunked_fetch, chunk_size=self.chunk_size
    )
  File "C:\Users\ResTIC16\Documents\cybersec-project\venv\Lib\site-packages\django\db\models\sql\compiler.py", line 1574, in execute_sql
    cursor.execute(sql, params)
    ~~~~~~~~~~~~~~^^^^^^^^^^^^^
  File "C:\Users\ResTIC16\Documents\cybersec-project\venv\Lib\site-packages\django\db\backends\utils.py", line 122, in execute
    return super().execute(sql, params)
           ~~~~~~~~~~~~~~~^^^^^^^^^^^^^
  File "C:\Users\ResTIC16\Documents\cybersec-project\venv\Lib\site-packages\django\db\backends\utils.py", line 79, in execute
    return self._execute_with_wrappers(
           ~~~~~~~~~~~~~~~~~~~~~~~~~~~^
        sql, params, many=False, executor=self._execute
        ^^^^^^^^^^^^^^^^^^^^^^^^^^^^^^^^^^^^^^^^^^^^^^^
    )
    ^
  File "C:\Users\ResTIC16\Documents\cybersec-project\venv\Lib\site-packages\django\db\backends\utils.py", line 92, in _execute_with_wrappers
    return executor(sql, params, many, context)
  File "C:\Users\ResTIC16\Documents\cybersec-project\venv\Lib\site-packages\django\db\backends\utils.py", line 100, in _execute
    with self.db.wrap_database_errors:
         ^^^^^^^^^^^^^^^^^^^^^^^^^^^^
  File "C:\Users\ResTIC16\Documents\cybersec-project\venv\Lib\site-packages\django\db\utils.py", line 91, in __exit__
    raise dj_exc_value.with_traceback(traceback) from exc_value
  File "C:\Users\ResTIC16\Documents\cybersec-project\venv\Lib\site-packages\django\db\backends\utils.py", line 105, in _execute
    return self.cursor.execute(sql, params)
           ~~~~~~~~~~~~~~~~~~~^^^^^^^^^^^^^
  File "C:\Users\ResTIC16\Documents\cybersec-project\venv\Lib\site-packages\django\db\backends\sqlite3\base.py", line 354, in execute
    return super().execute(query, params)
           ~~~~~~~~~~~~~~~^^^^^^^^^^^^^^^
django.db.utils.OperationalError: no such table: core_standard
WARNING 2025-03-20 09:57:24,309 signals Permissões do usuário Administrador foram alteradas.
WARNING 2025-03-20 09:57:24,323 signals Permissões do usuário Analista de Segurança foram alteradas.
WARNING 2025-03-20 13:40:44,950 signals PermissÃµes do usuÃ¡rio Administrador foram alteradas.
WARNING 2025-03-20 13:40:44,956 signals PermissÃµes do usuÃ¡rio Analista de SeguranÃ§a foram alteradas.
WARNING 2025-03-20 13:47:27,110 signals PermissÃµes do usuÃ¡rio Administrador foram alteradas.
WARNING 2025-03-20 13:47:27,117 signals PermissÃµes do usuÃ¡rio Analista de SeguranÃ§a foram alteradas.
WARNING 2025-03-20 13:50:59,789 signals PermissÃµes do usuÃ¡rio Administrador foram alteradas.
WARNING 2025-03-20 13:50:59,794 signals PermissÃµes do usuÃ¡rio Analista de SeguranÃ§a foram alteradas.
ERROR 2025-03-20 13:52:11,347 log Internal Server Error: /api/token/
Traceback (most recent call last):
  File "/usr/local/lib/python3.11/site-packages/django/db/backends/utils.py", line 105, in _execute
    return self.cursor.execute(sql, params)
           ^^^^^^^^^^^^^^^^^^^^^^^^^^^^^^^^
  File "/usr/local/lib/python3.11/site-packages/django/db/backends/sqlite3/base.py", line 354, in execute
    return super().execute(query, params)
           ^^^^^^^^^^^^^^^^^^^^^^^^^^^^^^
sqlite3.OperationalError: no such table: users_customuser

The above exception was the direct cause of the following exception:

Traceback (most recent call last):
  File "/usr/local/lib/python3.11/site-packages/django/core/handlers/exception.py", line 55, in inner
    response = get_response(request)
               ^^^^^^^^^^^^^^^^^^^^^
  File "/usr/local/lib/python3.11/site-packages/django/core/handlers/base.py", line 197, in _get_response
    response = wrapped_callback(request, *callback_args, **callback_kwargs)
               ^^^^^^^^^^^^^^^^^^^^^^^^^^^^^^^^^^^^^^^^^^^^^^^^^^^^^^^^^^^^
  File "/usr/local/lib/python3.11/site-packages/django/views/decorators/csrf.py", line 65, in _view_wrapper
    return view_func(request, *args, **kwargs)
           ^^^^^^^^^^^^^^^^^^^^^^^^^^^^^^^^^^^
  File "/usr/local/lib/python3.11/site-packages/django/views/generic/base.py", line 104, in view
    return self.dispatch(request, *args, **kwargs)
           ^^^^^^^^^^^^^^^^^^^^^^^^^^^^^^^^^^^^^^^
  File "/usr/local/lib/python3.11/site-packages/rest_framework/views.py", line 509, in dispatch
    response = self.handle_exception(exc)
               ^^^^^^^^^^^^^^^^^^^^^^^^^^
  File "/usr/local/lib/python3.11/site-packages/rest_framework/views.py", line 469, in handle_exception
    self.raise_uncaught_exception(exc)
  File "/usr/local/lib/python3.11/site-packages/rest_framework/views.py", line 480, in raise_uncaught_exception
    raise exc
  File "/usr/local/lib/python3.11/site-packages/rest_framework/views.py", line 506, in dispatch
    response = handler(request, *args, **kwargs)
               ^^^^^^^^^^^^^^^^^^^^^^^^^^^^^^^^^
  File "/usr/local/lib/python3.11/site-packages/rest_framework_simplejwt/views.py", line 44, in post
    serializer.is_valid(raise_exception=True)
  File "/usr/local/lib/python3.11/site-packages/rest_framework/serializers.py", line 223, in is_valid
    self._validated_data = self.run_validation(self.initial_data)
                           ^^^^^^^^^^^^^^^^^^^^^^^^^^^^^^^^^^^^^^
  File "/usr/local/lib/python3.11/site-packages/rest_framework/serializers.py", line 445, in run_validation
    value = self.validate(value)
            ^^^^^^^^^^^^^^^^^^^^
  File "/usr/local/lib/python3.11/site-packages/rest_framework_simplejwt/serializers.py", line 73, in validate
    data = super().validate(attrs)
           ^^^^^^^^^^^^^^^^^^^^^^^
  File "/usr/local/lib/python3.11/site-packages/rest_framework_simplejwt/serializers.py", line 54, in validate
    self.user = authenticate(**authenticate_kwargs)
                ^^^^^^^^^^^^^^^^^^^^^^^^^^^^^^^^^^^
  File "/usr/local/lib/python3.11/site-packages/django/views/decorators/debug.py", line 75, in sensitive_variables_wrapper
    return func(*func_args, **func_kwargs)
           ^^^^^^^^^^^^^^^^^^^^^^^^^^^^^^^
  File "/usr/local/lib/python3.11/site-packages/django/contrib/auth/__init__.py", line 79, in authenticate
    user = backend.authenticate(request, **credentials)
           ^^^^^^^^^^^^^^^^^^^^^^^^^^^^^^^^^^^^^^^^^^^^
  File "/usr/local/lib/python3.11/site-packages/django/contrib/auth/backends.py", line 42, in authenticate
    user = UserModel._default_manager.get_by_natural_key(username)
           ^^^^^^^^^^^^^^^^^^^^^^^^^^^^^^^^^^^^^^^^^^^^^^^^^^^^^^^
  File "/usr/local/lib/python3.11/site-packages/django/contrib/auth/base_user.py", line 37, in get_by_natural_key
    return self.get(**{self.model.USERNAME_FIELD: username})
           ^^^^^^^^^^^^^^^^^^^^^^^^^^^^^^^^^^^^^^^^^^^^^^^^^
  File "/usr/local/lib/python3.11/site-packages/django/db/models/manager.py", line 87, in manager_method
    return getattr(self.get_queryset(), name)(*args, **kwargs)
           ^^^^^^^^^^^^^^^^^^^^^^^^^^^^^^^^^^^^^^^^^^^^^^^^^^^
  File "/usr/local/lib/python3.11/site-packages/django/db/models/query.py", line 645, in get
    num = len(clone)
          ^^^^^^^^^^
  File "/usr/local/lib/python3.11/site-packages/django/db/models/query.py", line 382, in __len__
    self._fetch_all()
  File "/usr/local/lib/python3.11/site-packages/django/db/models/query.py", line 1928, in _fetch_all
    self._result_cache = list(self._iterable_class(self))
                         ^^^^^^^^^^^^^^^^^^^^^^^^^^^^^^^^
  File "/usr/local/lib/python3.11/site-packages/django/db/models/query.py", line 91, in __iter__
    results = compiler.execute_sql(
              ^^^^^^^^^^^^^^^^^^^^^
  File "/usr/local/lib/python3.11/site-packages/django/db/models/sql/compiler.py", line 1574, in execute_sql
    cursor.execute(sql, params)
  File "/usr/local/lib/python3.11/site-packages/django/db/backends/utils.py", line 122, in execute
    return super().execute(sql, params)
           ^^^^^^^^^^^^^^^^^^^^^^^^^^^^
  File "/usr/local/lib/python3.11/site-packages/django/db/backends/utils.py", line 79, in execute
    return self._execute_with_wrappers(
           ^^^^^^^^^^^^^^^^^^^^^^^^^^^^
  File "/usr/local/lib/python3.11/site-packages/django/db/backends/utils.py", line 92, in _execute_with_wrappers
    return executor(sql, params, many, context)
           ^^^^^^^^^^^^^^^^^^^^^^^^^^^^^^^^^^^^
  File "/usr/local/lib/python3.11/site-packages/django/db/backends/utils.py", line 100, in _execute
    with self.db.wrap_database_errors:
  File "/usr/local/lib/python3.11/site-packages/django/db/utils.py", line 91, in __exit__
    raise dj_exc_value.with_traceback(traceback) from exc_value
  File "/usr/local/lib/python3.11/site-packages/django/db/backends/utils.py", line 105, in _execute
    return self.cursor.execute(sql, params)
           ^^^^^^^^^^^^^^^^^^^^^^^^^^^^^^^^
  File "/usr/local/lib/python3.11/site-packages/django/db/backends/sqlite3/base.py", line 354, in execute
    return super().execute(query, params)
           ^^^^^^^^^^^^^^^^^^^^^^^^^^^^^^
django.db.utils.OperationalError: no such table: users_customuser
ERROR 2025-03-20 13:52:19,179 log Internal Server Error: /api/token/
Traceback (most recent call last):
  File "/usr/local/lib/python3.11/site-packages/django/db/backends/utils.py", line 105, in _execute
    return self.cursor.execute(sql, params)
           ^^^^^^^^^^^^^^^^^^^^^^^^^^^^^^^^
  File "/usr/local/lib/python3.11/site-packages/django/db/backends/sqlite3/base.py", line 354, in execute
    return super().execute(query, params)
           ^^^^^^^^^^^^^^^^^^^^^^^^^^^^^^
sqlite3.OperationalError: no such table: users_customuser

The above exception was the direct cause of the following exception:

Traceback (most recent call last):
  File "/usr/local/lib/python3.11/site-packages/django/core/handlers/exception.py", line 55, in inner
    response = get_response(request)
               ^^^^^^^^^^^^^^^^^^^^^
  File "/usr/local/lib/python3.11/site-packages/django/core/handlers/base.py", line 197, in _get_response
    response = wrapped_callback(request, *callback_args, **callback_kwargs)
               ^^^^^^^^^^^^^^^^^^^^^^^^^^^^^^^^^^^^^^^^^^^^^^^^^^^^^^^^^^^^
  File "/usr/local/lib/python3.11/site-packages/django/views/decorators/csrf.py", line 65, in _view_wrapper
    return view_func(request, *args, **kwargs)
           ^^^^^^^^^^^^^^^^^^^^^^^^^^^^^^^^^^^
  File "/usr/local/lib/python3.11/site-packages/django/views/generic/base.py", line 104, in view
    return self.dispatch(request, *args, **kwargs)
           ^^^^^^^^^^^^^^^^^^^^^^^^^^^^^^^^^^^^^^^
  File "/usr/local/lib/python3.11/site-packages/rest_framework/views.py", line 509, in dispatch
    response = self.handle_exception(exc)
               ^^^^^^^^^^^^^^^^^^^^^^^^^^
  File "/usr/local/lib/python3.11/site-packages/rest_framework/views.py", line 469, in handle_exception
    self.raise_uncaught_exception(exc)
  File "/usr/local/lib/python3.11/site-packages/rest_framework/views.py", line 480, in raise_uncaught_exception
    raise exc
  File "/usr/local/lib/python3.11/site-packages/rest_framework/views.py", line 506, in dispatch
    response = handler(request, *args, **kwargs)
               ^^^^^^^^^^^^^^^^^^^^^^^^^^^^^^^^^
  File "/usr/local/lib/python3.11/site-packages/rest_framework_simplejwt/views.py", line 44, in post
    serializer.is_valid(raise_exception=True)
  File "/usr/local/lib/python3.11/site-packages/rest_framework/serializers.py", line 223, in is_valid
    self._validated_data = self.run_validation(self.initial_data)
                           ^^^^^^^^^^^^^^^^^^^^^^^^^^^^^^^^^^^^^^
  File "/usr/local/lib/python3.11/site-packages/rest_framework/serializers.py", line 445, in run_validation
    value = self.validate(value)
            ^^^^^^^^^^^^^^^^^^^^
  File "/usr/local/lib/python3.11/site-packages/rest_framework_simplejwt/serializers.py", line 73, in validate
    data = super().validate(attrs)
           ^^^^^^^^^^^^^^^^^^^^^^^
  File "/usr/local/lib/python3.11/site-packages/rest_framework_simplejwt/serializers.py", line 54, in validate
    self.user = authenticate(**authenticate_kwargs)
                ^^^^^^^^^^^^^^^^^^^^^^^^^^^^^^^^^^^
  File "/usr/local/lib/python3.11/site-packages/django/views/decorators/debug.py", line 75, in sensitive_variables_wrapper
    return func(*func_args, **func_kwargs)
           ^^^^^^^^^^^^^^^^^^^^^^^^^^^^^^^
  File "/usr/local/lib/python3.11/site-packages/django/contrib/auth/__init__.py", line 79, in authenticate
    user = backend.authenticate(request, **credentials)
           ^^^^^^^^^^^^^^^^^^^^^^^^^^^^^^^^^^^^^^^^^^^^
  File "/usr/local/lib/python3.11/site-packages/django/contrib/auth/backends.py", line 42, in authenticate
    user = UserModel._default_manager.get_by_natural_key(username)
           ^^^^^^^^^^^^^^^^^^^^^^^^^^^^^^^^^^^^^^^^^^^^^^^^^^^^^^^
  File "/usr/local/lib/python3.11/site-packages/django/contrib/auth/base_user.py", line 37, in get_by_natural_key
    return self.get(**{self.model.USERNAME_FIELD: username})
           ^^^^^^^^^^^^^^^^^^^^^^^^^^^^^^^^^^^^^^^^^^^^^^^^^
  File "/usr/local/lib/python3.11/site-packages/django/db/models/manager.py", line 87, in manager_method
    return getattr(self.get_queryset(), name)(*args, **kwargs)
           ^^^^^^^^^^^^^^^^^^^^^^^^^^^^^^^^^^^^^^^^^^^^^^^^^^^
  File "/usr/local/lib/python3.11/site-packages/django/db/models/query.py", line 645, in get
    num = len(clone)
          ^^^^^^^^^^
  File "/usr/local/lib/python3.11/site-packages/django/db/models/query.py", line 382, in __len__
    self._fetch_all()
  File "/usr/local/lib/python3.11/site-packages/django/db/models/query.py", line 1928, in _fetch_all
    self._result_cache = list(self._iterable_class(self))
                         ^^^^^^^^^^^^^^^^^^^^^^^^^^^^^^^^
  File "/usr/local/lib/python3.11/site-packages/django/db/models/query.py", line 91, in __iter__
    results = compiler.execute_sql(
              ^^^^^^^^^^^^^^^^^^^^^
  File "/usr/local/lib/python3.11/site-packages/django/db/models/sql/compiler.py", line 1574, in execute_sql
    cursor.execute(sql, params)
  File "/usr/local/lib/python3.11/site-packages/django/db/backends/utils.py", line 122, in execute
    return super().execute(sql, params)
           ^^^^^^^^^^^^^^^^^^^^^^^^^^^^
  File "/usr/local/lib/python3.11/site-packages/django/db/backends/utils.py", line 79, in execute
    return self._execute_with_wrappers(
           ^^^^^^^^^^^^^^^^^^^^^^^^^^^^
  File "/usr/local/lib/python3.11/site-packages/django/db/backends/utils.py", line 92, in _execute_with_wrappers
    return executor(sql, params, many, context)
           ^^^^^^^^^^^^^^^^^^^^^^^^^^^^^^^^^^^^
  File "/usr/local/lib/python3.11/site-packages/django/db/backends/utils.py", line 100, in _execute
    with self.db.wrap_database_errors:
  File "/usr/local/lib/python3.11/site-packages/django/db/utils.py", line 91, in __exit__
    raise dj_exc_value.with_traceback(traceback) from exc_value
  File "/usr/local/lib/python3.11/site-packages/django/db/backends/utils.py", line 105, in _execute
    return self.cursor.execute(sql, params)
           ^^^^^^^^^^^^^^^^^^^^^^^^^^^^^^^^
  File "/usr/local/lib/python3.11/site-packages/django/db/backends/sqlite3/base.py", line 354, in execute
    return super().execute(query, params)
           ^^^^^^^^^^^^^^^^^^^^^^^^^^^^^^
django.db.utils.OperationalError: no such table: users_customuser
WARNING 2025-03-20 11:15:53,568 signals Permissões do usuário Administrador foram alteradas.
WARNING 2025-03-20 11:15:53,569 signals Permissões do usuário Analista de Segurança foram alteradas.
WARNING 2025-03-20 11:18:25,038 signals Permissões do usuário Administrador foram alteradas.
WARNING 2025-03-20 11:18:25,040 signals Permissões do usuário Analista de Segurança foram alteradas.
WARNING 2025-03-20 11:22:36,246 signals Permissões do usuário Administrador foram alteradas.
WARNING 2025-03-20 11:22:36,247 signals Permissões do usuário Analista de Segurança foram alteradas.
WARNING 2025-03-20 11:31:21,039 signals Permissões do usuário Administrador foram alteradas.
WARNING 2025-03-20 11:31:21,050 signals Permissões do usuário Analista de Segurança foram alteradas.
WARNING 2025-03-20 11:50:13,499 signals Permissões do usuário Administrador foram alteradas.
WARNING 2025-03-20 11:50:13,502 signals Permissões do usuário Analista de Segurança foram alteradas.
WARNING 2025-03-20 12:00:19,603 signals Permissões do usuário Administrador foram alteradas.
WARNING 2025-03-20 12:00:19,604 signals Permissões do usuário Analista de Segurança foram alteradas.
WARNING 2025-03-20 12:10:59,843 signals Permissões do usuário Administrador foram alteradas.
WARNING 2025-03-20 12:10:59,845 signals Permissões do usuário Analista de Segurança foram alteradas.
WARNING 2025-03-20 12:19:08,023 signals Permissões do usuário Administrador foram alteradas.
WARNING 2025-03-20 12:19:08,025 signals Permissões do usuário Analista de Segurança foram alteradas.
WARNING 2025-03-20 15:19:56,651 signals PermissÃµes do usuÃ¡rio Administrador foram alteradas.
WARNING 2025-03-20 15:19:56,654 signals PermissÃµes do usuÃ¡rio Analista de SeguranÃ§a foram alteradas.
WARNING 2025-03-20 12:20:36,754 signals Permissões do usuário Administrador foram alteradas.
WARNING 2025-03-20 12:20:36,756 signals Permissões do usuário Analista de Segurança foram alteradas.
WARNING 2025-03-20 15:21:09,543 signals PermissÃµes do usuÃ¡rio Administrador foram alteradas.
WARNING 2025-03-20 15:21:09,547 signals PermissÃµes do usuÃ¡rio Analista de SeguranÃ§a foram alteradas.
WARNING 2025-03-20 15:34:21,405 signals PermissÃµes do usuÃ¡rio Administrador foram alteradas.
WARNING 2025-03-20 15:34:21,409 signals PermissÃµes do usuÃ¡rio Analista de SeguranÃ§a foram alteradas.
WARNING 2025-03-20 15:44:05,826 signals PermissÃµes do usuÃ¡rio Administrador foram alteradas.
WARNING 2025-03-20 15:44:05,832 signals PermissÃµes do usuÃ¡rio Analista de SeguranÃ§a foram alteradas.
WARNING 2025-03-20 15:51:39,568 signals PermissÃµes do usuÃ¡rio Administrador foram alteradas.
WARNING 2025-03-20 15:51:39,572 signals PermissÃµes do usuÃ¡rio Analista de SeguranÃ§a foram alteradas.
WARNING 2025-03-20 16:26:56,103 signals PermissÃµes do usuÃ¡rio Administrador foram alteradas.
WARNING 2025-03-20 16:26:56,105 signals PermissÃµes do usuÃ¡rio Analista de SeguranÃ§a foram alteradas.
WARNING 2025-03-20 16:35:03,659 signals PermissÃµes do usuÃ¡rio Administrador foram alteradas.
WARNING 2025-03-20 16:35:03,662 signals PermissÃµes do usuÃ¡rio Analista de SeguranÃ§a foram alteradas.
WARNING 2025-03-20 19:02:37,683 signals PermissÃµes do usuÃ¡rio Administrador foram alteradas.
WARNING 2025-03-20 19:02:37,687 signals PermissÃµes do usuÃ¡rio Analista de SeguranÃ§a foram alteradas.
WARNING 2025-03-20 20:04:06,070 signals PermissÃµes do usuÃ¡rio Administrador foram alteradas.
WARNING 2025-03-20 20:04:06,074 signals PermissÃµes do usuÃ¡rio Analista de SeguranÃ§a foram alteradas.
WARNING 2025-03-20 21:34:48,576 signals PermissÃµes do usuÃ¡rio Administrador foram alteradas.
WARNING 2025-03-20 21:34:48,585 signals PermissÃµes do usuÃ¡rio Analista de SeguranÃ§a foram alteradas.
WARNING 2025-03-21 11:07:38,352 signals PermissÃµes do usuÃ¡rio Administrador foram alteradas.
WARNING 2025-03-21 11:07:38,360 signals PermissÃµes do usuÃ¡rio Analista de SeguranÃ§a foram alteradas.
WARNING 2025-03-21 11:53:21,386 signals PermissÃµes do usuÃ¡rio Administrador foram alteradas.
WARNING 2025-03-21 11:53:21,391 signals PermissÃµes do usuÃ¡rio Analista de SeguranÃ§a foram alteradas.
WARNING 2025-03-21 12:21:06,269 signals PermissÃµes do usuÃ¡rio Administrador foram alteradas.
WARNING 2025-03-21 12:21:06,273 signals PermissÃµes do usuÃ¡rio Analista de SeguranÃ§a foram alteradas.
WARNING 2025-03-21 13:13:51,257 signals PermissÃµes do usuÃ¡rio Administrador foram alteradas.
WARNING 2025-03-21 13:13:51,263 signals PermissÃµes do usuÃ¡rio Analista de SeguranÃ§a foram alteradas.
WARNING 2025-03-21 13:18:39,731 signals PermissÃµes do usuÃ¡rio Administrador foram alteradas.
WARNING 2025-03-21 13:18:39,735 signals PermissÃµes do usuÃ¡rio Analista de SeguranÃ§a foram alteradas.
WARNING 2025-03-21 11:05:18,155 signals Permissões do usuário Administrador foram alteradas.
WARNING 2025-03-21 11:05:18,157 signals Permissões do usuário Analista de Segurança foram alteradas.
WARNING 2025-03-21 11:43:15,937 signals Permissões do usuário Administrador foram alteradas.
WARNING 2025-03-21 11:43:15,938 signals Permissões do usuário Analista de Segurança foram alteradas.
WARNING 2025-03-21 11:52:17,220 signals Permissões do usuário Administrador foram alteradas.
WARNING 2025-03-21 11:52:17,221 signals Permissões do usuário Analista de Segurança foram alteradas.
WARNING 2025-03-21 15:06:54,755 signals PermissÃµes do usuÃ¡rio Administrador foram alteradas.
WARNING 2025-03-21 15:06:54,760 signals PermissÃµes do usuÃ¡rio Analista de SeguranÃ§a foram alteradas.
WARNING 2025-03-21 15:32:24,382 signals PermissÃµes do usuÃ¡rio Administrador foram alteradas.
WARNING 2025-03-21 15:32:24,387 signals PermissÃµes do usuÃ¡rio Analista de SeguranÃ§a foram alteradas.
WARNING 2025-03-21 15:43:48,116 signals PermissÃµes do usuÃ¡rio Administrador foram alteradas.
WARNING 2025-03-21 15:43:48,124 signals PermissÃµes do usuÃ¡rio Analista de SeguranÃ§a foram alteradas.
WARNING 2025-03-21 15:48:10,009 signals PermissÃµes do usuÃ¡rio Administrador foram alteradas.
WARNING 2025-03-21 15:48:10,014 signals PermissÃµes do usuÃ¡rio Analista de SeguranÃ§a foram alteradas.
WARNING 2025-03-21 15:54:45,909 signals PermissÃµes do usuÃ¡rio Administrador foram alteradas.
WARNING 2025-03-21 15:54:45,914 signals PermissÃµes do usuÃ¡rio Analista de SeguranÃ§a foram alteradas.
WARNING 2025-03-21 16:06:19,913 signals PermissÃµes do usuÃ¡rio Administrador foram alteradas.
WARNING 2025-03-21 16:06:19,919 signals PermissÃµes do usuÃ¡rio Analista de SeguranÃ§a foram alteradas.
WARNING 2025-03-21 16:13:42,031 signals PermissÃµes do usuÃ¡rio Administrador foram alteradas.
WARNING 2025-03-21 16:13:42,035 signals PermissÃµes do usuÃ¡rio Analista de SeguranÃ§a foram alteradas.
WARNING 2025-03-21 16:18:09,416 signals PermissÃµes do usuÃ¡rio Administrador foram alteradas.
WARNING 2025-03-21 16:18:09,422 signals PermissÃµes do usuÃ¡rio Analista de SeguranÃ§a foram alteradas.
WARNING 2025-03-21 20:07:58,929 signals PermissÃµes do usuÃ¡rio Administrador foram alteradas.
WARNING 2025-03-21 20:07:58,935 signals PermissÃµes do usuÃ¡rio Analista de SeguranÃ§a foram alteradas.
WARNING 2025-03-21 20:09:02,548 signals PermissÃµes do usuÃ¡rio Administrador foram alteradas.
WARNING 2025-03-21 20:09:02,551 signals PermissÃµes do usuÃ¡rio Analista de SeguranÃ§a foram alteradas.
WARNING 2025-03-21 21:32:19,140 signals PermissÃµes do usuÃ¡rio Administrador foram alteradas.
WARNING 2025-03-21 21:32:19,144 signals PermissÃµes do usuÃ¡rio Analista de SeguranÃ§a foram alteradas.
WARNING 2025-03-22 11:53:57,880 signals PermissÃµes do usuÃ¡rio Administrador foram alteradas.
WARNING 2025-03-22 11:53:57,916 signals PermissÃµes do usuÃ¡rio Analista de SeguranÃ§a foram alteradas.
WARNING 2025-03-22 13:19:14,809 signals PermissÃµes do usuÃ¡rio Administrador foram alteradas.
WARNING 2025-03-22 13:19:14,814 signals PermissÃµes do usuÃ¡rio Analista de SeguranÃ§a foram alteradas.
WARNING 2025-03-22 15:08:50,257 signals PermissÃµes do usuÃ¡rio Administrador foram alteradas.
WARNING 2025-03-22 15:08:50,267 signals PermissÃµes do usuÃ¡rio Analista de SeguranÃ§a foram alteradas.
WARNING 2025-03-26 11:44:02,726 signals PermissÃµes do usuÃ¡rio Administrador foram alteradas.
WARNING 2025-03-26 11:44:02,730 signals PermissÃµes do usuÃ¡rio Analista de SeguranÃ§a foram alteradas.
WARNING 2025-03-26 11:50:05,033 signals PermissÃµes do usuÃ¡rio Administrador foram alteradas.
WARNING 2025-03-26 11:50:05,037 signals PermissÃµes do usuÃ¡rio Analista de SeguranÃ§a foram alteradas.
WARNING 2025-03-26 11:46:52,539 signals Permissões do usuário Administrador foram alteradas.
WARNING 2025-03-26 11:46:52,544 signals Permissões do usuário Analista de Segurança foram alteradas.
WARNING 2025-03-26 15:18:15,947 signals PermissÃµes do usuÃ¡rio Administrador foram alteradas.
WARNING 2025-03-26 15:18:15,955 signals PermissÃµes do usuÃ¡rio Analista de SeguranÃ§a foram alteradas.
